Workbook

Sheet Dutch Carbon Budget
D1: 1,5ºC | E1: 1,7ºC | F1: 2,0ºC | G1: Unit | H1: Source
B2: Global | C2: Global CB 2024 in Mt CO2 | D2: 150000 | E2: 450000 | F2: 900000 | G2: Mt CO2 | H2: (Forster et al., 2024)
A4: Per capita approach | B4: Global | C4: Global Population | D4: 7951150000 | E4: 7951150000 | F4: 7951150000 | G4: # | H4: (World Bank, 2023b)
B5: Dutch | C5: Dutch Population | D5: 17811291 | E5: 17811291 | F5: 17811291 | G5: # | H5: (Statistics Netherlands, 2023)
C6: Dutch share (Population) | D6: =D5/D4 -> 0.0022400899 | E6: =E5/E4 -> 0.0022400899 | F6: =F5/F4 -> 0.0022400899 | G6: %
C7: Dutch CB 2023 in Mt CO2 | D7: =D2*D6 -> 336.01349 | E7: =E2*E6 -> 1008.0405 | F7: =F2*F6 -> 2016.0809 | G7: Mt CO2
C8: Dutch CB 2023 per 2023 capita in t CO2 | D8: =D7/D5*1000000 -> 18.865196 | E8: =E7/E5*1000000 -> 56.595587 | F8: =F7/F5*1000000 -> 113.19117 | G8: t CO2
C9: Years until Dutch carbon neutrality target by 2050 | D9: =2050-2024 -> 26 | E9: =2050-2024 -> 26 | F9: =2050-2024 -> 26 | G9: years
C10: Annual per capita carbon budget until net zero | D10: =D8/D9 -> 0.72558445 | E10: =E8/E9 -> 2.1767533 | F10: =F8/F9 -> 4.3535067 | G10: t CO2
A12: GDP approach | B12: Global | C12: Global GDP 2022 | D12: 101002997 | E12: 101002997 | F12: 101002997 | G12: $ | H12: (World Bank 2023a)
B13: Dutch | C13: Dutch GDP | D13: 991115 | E13: 991115 | F13: 991115 | G13: $ | H13: (World Bank 2023a)
C14: Dutch share (GDP) | D14: =D13/D12 -> 0.0098127286 | E14: =E13/E12 -> 0.0098127286 | F14: =F13/F12 -> 0.0098127286 | G14: %
C15: Dutch CB 2023 in Mt | D15: =D2*D14 -> 1471.9093 | E15: =E2*E14 -> 4415.7279 | F15: =F2*F14 -> 8831.4558 | G15: Mt CO2
C16: Dutch CB 2023 per 2023 capita in t CO2 | D16: =D15/D5*1000000 -> 82.639113 | E16: =E15/E5*1000000 -> 247.91734 | F16: =F15/F5*1000000 -> 495.83468 | G16: t CO2
C17: Annual per capita carbon budget until net zero | D17: =D16/D9 -> 3.1784274 | E17: =E16/E9 -> 9.5352823 | F17: =F16/F9 -> 19.070565 | G17: t CO2
A19: Continuing with historic level | B19: Global | C19: Global Emissions in 2021 | D19: 37120 | E19: 37120 | F19: 37120 | G19: Mt CO2 | H19: (Ritchie et al. 2020)
B20: Dutch | C20: Dutch Emissions, consumption-based 2021 | D20: 152 | E20: 152 | F20: 152 | G20: Mt CO2 | H20: (Ritchie et al. 2020)
C21: Dutch share (Emissions) | D21: =D20/D19 -> 0.0040948276 | E21: =E20/E19 -> 0.0040948276 | F21: =F20/F19 -> 0.0040948276 | G21: %
C22: Dutch CB 2023 | D22: =D21*D2 -> 614.22414 | E22: =E21*E2 -> 1842.6724 | F22: =F21*F2 -> 3685.3448 | G22: Mt CO2
C23: Dutch CB 2023 per 2023 capita | D23: =D22/D5*1000000 -> 34.485099 | E23: =E22/E5*1000000 -> 103.4553 | F23: =F22/F5*1000000 -> 206.9106 | G23: t CO2
C24: Annual per capita carbon budget until net zero | D24: =D23/D9 -> 1.32635 | E24: =E23/E9 -> 3.9790499 | F24: =F23/F9 -> 7.9580998 | G24: t CO2
A26: Cumulative historic responsibility | B26: Global | C26: Global cumulative emissions until 2021 in billion tones CO2 | D26: 1740000 | E26: 1740000 | F26: 1740000 | G26: Mt CO2 | H26: (Ritchie et al. 2020)
B27: Dutch | C27: Dutch cumulative emissions until 2021 in Mt | D27: 11800 | E27: 11800 | F27: 11800 | G27: Mt CO2 | H27: (Ritchie et al. 2020)
C28: Dutch share (cumulative Emissions) | D28: =D27/D26 -> 0.0067816092 | E28: =E27/E26 -> 0.0067816092 | F28: =F27/F26 -> 0.0067816092 | G28: %
C29: Dutch hypothetical cumulative emissions per capita 2021 in Mt | D29: =D26*D6 -> 3897.7565 | E29: =E26*E6 -> 3897.7565 | F29: =F26*F6 -> 3897.7565 | G29: Mt CO2
C30: Difference cumulative emissions (per capita vs. actual) | D30: =D29-D27 -> -7902.2435 | E30: =E29-E27 -> -7902.2435 | F30: =F29-F27 -> -7902.2435 | G30: Mt CO2
C31: Dutch CB per capita approach 2023 in Mt | D31: =D7 -> 336.01349 | E31: =E7 -> 1008.0405 | F31: =F7 -> 2016.0809 | G31: Mt CO2
C32: Dutch CB 2023 adjusted for cumulative emissions in Mt | D32: =D30+D31 -> -7566.23 | E32: =E30+E31 -> -6894.2031 | F32: =F30+F31 -> -5886.1626 | G32: Mt CO2
C33: Dutch CB 2023 per 2023 capita in t CO2 | D33: =D32/D5*1000000 -> -424.79964 | E33: =E32/E5*1000000 -> -387.06925 | F33: =F32/F5*1000000 -> -330.47366 | G33: t CO2
C34: Annual per capita carbon budget until net zero | D34: =D33/D9 -> -16.338448 | E34: =E33/E9 -> -14.887279 | F34: =F33/F9 -> -12.710526 | G34: t CO2
A37: Housing sector | B37: Dutch | C37: Share of shelter (construction, heating, electricity, etc.) of total carbon footprint in 2011 | D37: 0.264 | E37: 0.264 | F37: 0.264 | H37: (Exiobase3)
C38: Share of mobility (car, rail, flights etc.) of total carbon footprint in 2011 | D38: 0.094 | E38: 0.094 | F38: 0.094 | H38: (Exiobase3)
C39: Total % Share of housing sector | D39: =D37+D38 -> 0.358 | E39: =E37+E38 -> 0.358 | F39: =F37+F38 -> 0.358
C43: Annual per capita carbon budget of housing sector until carbon neutrality in 2050
C44: t | D44: 1,5ºC | E44: 1,7ºC | F44: 2,0ºC | G44: 67% probability of not exceeding global warming limit
C45: Per capita adjusted by cumulative historic emissions | D45: =D34*D39 -> -5.8491643 | E45: =E34*E39 -> -5.3296458 | F45: =F34*F39 -> -4.5503681 | G45: t CO2 per capita per year as of 2024
C46: Per capita | D46: =D10*D39 -> 0.25975923 | E46: =E10*E39 -> 0.7792777 | F46: =F10*F39 -> 1.5585554 | G46: t CO2 per capita per year as of 2024
C47: Per current emissions | D47: =D24*D39 -> 0.47483329 | E47: =E24*E39 -> 1.4244999 | F47: =F24*F39 -> 2.8489997 | G47: t CO2 per capita per year as of 2024
C48: Per current economic output | D48: =D17*D39 -> 1.137877 | E48: =E17*E39 -> 3.4136311 | F48: =F17*F39 -> 6.8272621 | G48: t CO2 per capita per year as of 2024
C50: Dutch carbon budget
...

Sheet Sheet2
C1: 1,5ºC | D1: 1,7ºC | E1: 2,0ºC | F1: Unit | G1: Source
B2: Global CB 2024 in Mt CO2 | C2: 150000 | D2: 450000 | E2: 900000 | F2: Mt CO2 | G2: (Forster et al., 2024)
A4: Per capita approach | B4: Global Population | C4: 7951150000 | D4: 7951150000 | E4: 7951150000 | F4: # | G4: (World Bank, 2023b)
B5: Dutch Population | C5: 17811291 | D5: 17811291 | E5: 17811291 | F5: # | G5: (Statistics Netherlands, 2023)
B6: Dutch share (Population) | C6: =C5/C4 -> 0.0022400899 | D6: =D5/D4 -> 0.0022400899 | E6: =E5/E4 -> 0.0022400899 | F6: %
B7: Dutch CB 2023 in Mt CO2 | C7: =C2*C6 -> 336.01349 | D7: =D2*D6 -> 1008.0405 | E7: =E2*E6 -> 2016.0809 | F7: Mt CO2
B8: Dutch CB 2023 per 2023 capita in t CO2 | C8: =C7/C5*1000000 -> 18.865196 | D8: =D7/D5*1000000 -> 56.595587 | E8: =E7/E5*1000000 -> 113.19117 | F8: t CO2
B9: Years until Dutch carbon neutrality target by 2050 | C9: =2050-2024 -> 26 | D9: =2050-2024 -> 26 | E9: =2050-2024 -> 26 | F9: years
B10: Annual per capita carbon budget until net zero | C10: =C8/C9 -> 0.72558445 | D10: =D8/D9 -> 2.1767533 | E10: =E8/E9 -> 4.3535067 | F10: t CO2
A12: Cumulative historic responsibility | B12: Global cumulative emissions until 2021 in billion tones CO2 | C12: 1740000 | D12: 1740000 | E12: 1740000 | F12: Mt CO2 | G12: (Ritchie et al. 2020)
B13: Dutch cumulative emissions until 2021 in Mt | C13: 11800 | D13: 11800 | E13: 11800 | F13: Mt CO2 | G13: (Ritchie et al. 2020)
B14: Dutch share (cumulative Emissions) | C14: =C13/C12 -> 0.0067816092 | D14: =D13/D12 -> 0.0067816092 | E14: =E13/E12 -> 0.0067816092 | F14: %
B15: Dutch hypothetical cumulative emissions per capita 2021 in Mt | C15: =C12*C6 -> 3897.7565 | D15: =D12*D6 -> 3897.7565 | E15: =E12*E6 -> 3897.7565 | F15: Mt CO2
B16: Difference cumulative emissions (per capita vs. actual) | C16: =C15-C13 -> -7902.2435 | D16: =D15-D13 -> -7902.2435 | E16: =E15-E13 -> -7902.2435 | F16: Mt CO2
B17: Dutch CB per capita approach 2023 in Mt | C17: =C7 -> 336.01349 | D17: =D7 -> 1008.0405 | E17: =E7 -> 2016.0809 | F17: Mt CO2
B18: Dutch CB 2023 adjusted for cumulative emissions in Mt | C18: =C16+C17 -> -7566.23 | D18: =D16+D17 -> -6894.2031 | E18: =E16+E17 -> -5886.1626 | F18: Mt CO2
B19: Dutch CB 2023 per 2023 capita in t CO2 | C19: =C18/C5*1000000 -> -424.79964 | D19: =D18/D5*1000000 -> -387.06925 | E19: =E18/E5*1000000 -> -330.47366 | F19: t CO2
B20: Annual per capita carbon budget until net zero | C20: =C19/C9 -> -16.338448 | D20: =D19/D9 -> -14.887279 | E20: =E19/E9 -> -12.710526 | F20: t CO2
A22: Housing sector | B22: Share of shelter (construction, heating, electricity, etc.) of total carbon footprint in 2011 | C22: 0.264 | D22: 0.264 | E22: 0.264 | G22: (Exiobase3)
B23: Share of mobility (car, rail, flights etc.) of total carbon footprint in 2011 | C23: 0.094 | D23: 0.094 | E23: 0.094 | G23: (Exiobase3)
B24: Total % Share of housing sector | C24: =C22+C23 -> 0.358 | D24: =D22+D23 -> 0.358 | E24: =E22+E23 -> 0.358
B27: Annual per capita carbon budget of housing sector until carbon neutrality in 2050
B28: t | C28: 1,5ºC | D28: 1,7ºC | E28: 2,0ºC | F28: 67% probability of not exceeding global warming limit
B29: Per capita adjusted by cumulative historic emissions | C29: =C20*C24 -> -5.8491643 | D29: =D20*D24 -> -5.3296458 | E29: =E20*E24 -> -4.5503681 | F29: t CO2 per capita per year as of 2024
B30: Per capita | C30: =C10*C24 -> 0.25975923 | D30: =D10*D24 -> 0.7792777 | E30: =E10*E24 -> 1.5585554 | F30: t CO2 per capita per year as of 2024
B32: Dutch carbon budget
B33: Mt | C33: 1,5ºC | D33: 1,7ºC | E33: 2,0ºC | F33: 67% probability of not exceeding global warming limit
B34: Per capita adjusted by cumulative historic emissions | C34: =C18 -> -7566.23 | D34: =D18 -> -6894.2031 | E34: =E18 -> -5886.1626 | F34: t CO2 per capita per year as of 2024
B35: Per capita | C35: =C7 -> 336.01349 | D35: =D7 -> 1008.0405 | E35: =E7 -> 2016.0809 | F35: t CO2 per capita per year as of 2024

Sheet Sheet1
B1: tenure | F1: income
B2: kg CO2e total | C2: capita | D2: kg CO2e per capita per year | F2: kg CO2e total | G2: capita | H2: kg CO2e per capita
A3: 2019 | B3: 7.6249806e+10 | C3: 15815860 | D3: =B3/C3 -> 4821.0977 | F3: 7.0666275e+10 | G3: 15838600 | H3: =F3/G3 -> 4461.6491
A4: 2023 | B4: 6.8044047e+10 | C4: 16239855 | D4: =B4/C4 -> 4189.9418 | F4: 6.2883159e+10 | G4: 16247430 | H4: =F4/G4 -> 3870.345
C5: 17400000 | G5: 17400000
A7: Years after which carbon budget will be used up with 2019 emissions | F7: Years after which carbon budget will be used up
B8: 1,5ºC | C8: 1,7ºC | D8: 2,0ºC | G8: 1,5ºC | H8: 1,7ºC | I8: 2,0ºC
A9: Per capita adjusted by cumulative historic emissions | B9: ='Dutch Carbon Budget'!D52*1000000000/Sheet1!$B$3*$C$3/$C$5 -> -90.195395 | C9: ='Dutch Carbon Budget'!E52*1000000000/Sheet1!$B$3*$C$3/$C$5 -> -82.184306 | D9: ='Dutch Carbon Budget'!F52*1000000000/Sheet1!$B$3*$C$3/$C$5 -> -70.167673 | F9: Per capita adjusted by cumulative historic emissions | G9: ='Dutch Carbon Budget'!D52*1000000000/Sheet1!$F$3*$G$3/$G$5 -> -97.461902 | H9: ='Dutch Carbon Budget'!E52*1000000000/Sheet1!$F$3*$G$3/$G$5 -> -88.805408 | I9: ='Dutch Carbon Budget'!F52*1000000000/Sheet1!$F$3*$G$3/$G$5 -> -75.820666
A10: Per capita | B10: ='Dutch Carbon Budget'!D53*1000000000/Sheet1!$B$3*$C$3/$C$5 -> 4.0055442 | C10: ='Dutch Carbon Budget'!E53*1000000000/Sheet1!$B$3*$C$3/$C$5 -> 12.016633 | D10: ='Dutch Carbon Budget'!F53*1000000000/Sheet1!$B$3*$C$3/$C$5 -> 24.033265 | F10: Per capita | G10: ='Dutch Carbon Budget'!D53*1000000000/Sheet1!$F$3*$G$3/$G$5 -> 4.3282472 | H10: ='Dutch Carbon Budget'!E53*1000000000/Sheet1!$F$3*$G$3/$G$5 -> 12.984741 | I10: ='Dutch Carbon Budget'!F53*1000000000/Sheet1!$F$3*$G$3/$G$5 -> 25.969483
A11: Per current emissions | B11: ='Dutch Carbon Budget'!D54*1000000000/Sheet1!$B$3*$C$3/$C$5 -> 7.3220333 | C11: ='Dutch Carbon Budget'!E54*1000000000/Sheet1!$B$3*$C$3/$C$5 -> 21.9661 | D11: ='Dutch Carbon Budget'!F54*1000000000/Sheet1!$B$3*$C$3/$C$5 -> 43.9322 | F11: Per current emissions | G11: ='Dutch Carbon Budget'!D54*1000000000/Sheet1!$F$3*$G$3/$G$5 -> 7.9119261 | H11: ='Dutch Carbon Budget'!E54*1000000000/Sheet1!$F$3*$G$3/$G$5 -> 23.735778 | I11: ='Dutch Carbon Budget'!F54*1000000000/Sheet1!$F$3*$G$3/$G$5 -> 47.471556
A12: Per current economic output | B12: ='Dutch Carbon Budget'!D55*1000000000/Sheet1!$B$3*$C$3/$C$5 -> 17.546313 | C12: ='Dutch Carbon Budget'!E55*1000000000/Sheet1!$B$3*$C$3/$C$5 -> 52.638939 | D12: ='Dutch Carbon Budget'!F55*1000000000/Sheet1!$B$3*$C$3/$C$5 -> 105.27788 | F12: Per current economic output | G12: ='Dutch Carbon Budget'!D55*1000000000/Sheet1!$F$3*$G$3/$G$5 -> 18.959915 | H12: ='Dutch Carbon Budget'!E55*1000000000/Sheet1!$F$3*$G$3/$G$5 -> 56.879745 | I12: ='Dutch Carbon Budget'!F55*1000000000/Sheet1!$F$3*$G$3/$G$5 -> 113.75949
A14: Years after which carbon budget will be used up with 2023 emissions | F14: Years after which carbon budget will be used up
B15: 1,5ºC | C15: 1,7ºC | D15: 2,0ºC | G15: 1,5ºC | H15: 1,7ºC | I15: 2,0ºC
A16: Per capita adjusted by cumulative historic emissions | B16: ='Dutch Carbon Budget'!D52*1000000000/Sheet1!$B$4*$C$4/$C$5 -> -103.78206 | C16: ='Dutch Carbon Budget'!E52*1000000000/Sheet1!$B$4*$C$4/$C$5 -> -94.564217 | D16: ='Dutch Carbon Budget'!F52*1000000000/Sheet1!$B$4*$C$4/$C$5 -> -80.737448 | F16: Per capita adjusted by cumulative historic emissions | G16: ='Dutch Carbon Budget'!D52*1000000000/Sheet1!$F$4*$G$4/$G$5 -> -112.35195 | H16: ='Dutch Carbon Budget'!E52*1000000000/Sheet1!$F$4*$G$4/$G$5 -> -102.37293 | I16: ='Dutch Carbon Budget'!F52*1000000000/Sheet1!$F$4*$G$4/$G$5 -> -87.404407
A17: Per capita | B17: ='Dutch Carbon Budget'!D53*1000000000/Sheet1!$B$4*$C$4/$C$5 -> 4.6089232 | C17: ='Dutch Carbon Budget'!E53*1000000000/Sheet1!$B$4*$C$4/$C$5 -> 13.82677 | D17: ='Dutch Carbon Budget'!F53*1000000000/Sheet1!$B$4*$C$4/$C$5 -> 27.653539 | F17: Per capita | G17: ='Dutch Carbon Budget'!D53*1000000000/Sheet1!$F$4*$G$4/$G$5 -> 4.9895087 | H17: ='Dutch Carbon Budget'!E53*1000000000/Sheet1!$F$4*$G$4/$G$5 -> 14.968526 | I17: ='Dutch Carbon Budget'!F53*1000000000/Sheet1!$F$4*$G$4/$G$5 -> 29.937052
A18: Per current emissions | B18: ='Dutch Carbon Budget'!D54*1000000000/Sheet1!$B$4*$C$4/$C$5 -> 8.4249948 | C18: ='Dutch Carbon Budget'!E54*1000000000/Sheet1!$B$4*$C$4/$C$5 -> 25.274984 | D18: ='Dutch Carbon Budget'!F54*1000000000/Sheet1!$B$4*$C$4/$C$5 -> 50.549969 | F18: Per current emissions | G18: ='Dutch Carbon Budget'!D54*1000000000/Sheet1!$F$4*$G$4/$G$5 -> 9.1206954 | H18: ='Dutch Carbon Budget'!E54*1000000000/Sheet1!$F$4*$G$4/$G$5 -> 27.362086 | I18: ='Dutch Carbon Budget'!F54*1000000000/Sheet1!$F$4*$G$4/$G$5 -> 54.724173
A19: Per current economic output | B19: ='Dutch Carbon Budget'!D55*1000000000/Sheet1!$B$4*$C$4/$C$5 -> 20.189418 | C19: ='Dutch Carbon Budget'!E55*1000000000/Sheet1!$B$4*$C$4/$C$5 -> 60.568255 | D19: ='Dutch Carbon Budget'!F55*1000000000/Sheet1!$B$4*$C$4/$C$5 -> 121.13651 | F19: Per current economic output | G19: ='Dutch Carbon Budget'!D55*1000000000/Sheet1!$F$4*$G$4/$G$5 -> 21.856576 | H19: ='Dutch Carbon Budget'!E55*1000000000/Sheet1!$F$4*$G$4/$G$5 -> 65.569727 | I19: ='Dutch Carbon Budget'!F55*1000000000/Sheet1!$F$4*$G$4/$G$5 -> 131.13945
A22: 2019 | F22: 2019
A23: assuming only 38.5% of CB can be used for housing | F23: assuming only 38.5% of CB can be used for housing
B24: 1,5ºC | C24: 1,7ºC | D24: 2,0ºC | G24: 1,5ºC | H24: 1,7ºC | I24: 2,0ºC
A25: Per capita adjusted by cumulative historic emissions | B25: =B9*'Dutch Carbon Budget'!$D$39 -> -32.289951 | C25: =C9*'Dutch Carbon Budget'!$D$39 -> -29.421982 | D25: =D9*'Dutch Carbon Budget'!$D$39 -> -25.120027 | F25: Per capita adjusted by cumulative historic emissions | G25: =G9*'Dutch Carbon Budget'!$D$39 -> -34.891361 | H25: =H9*'Dutch Carbon Budget'!$D$39 -> -31.792336 | I25: =I9*'Dutch Carbon Budget'!$D$39 -> -27.143799
A26: Per capita | B26: =B10*'Dutch Carbon Budget'!$D$39 -> 1.4339848 | C26: =C10*'Dutch Carbon Budget'!$D$39 -> 4.3019545 | D26: =D10*'Dutch Carbon Budget'!$D$39 -> 8.603909 | F26: Per capita | G26: =G10*'Dutch Carbon Budget'!$D$39 -> 1.5495125 | H26: =H10*'Dutch Carbon Budget'!$D$39 -> 4.6485375 | I26: =I10*'Dutch Carbon Budget'!$D$39 -> 9.2970749
A27: Per current emissions | B27: =B11*'Dutch Carbon Budget'!$D$39 -> 2.6212879 | C27: =C11*'Dutch Carbon Budget'!$D$39 -> 7.8638638 | D27: =D11*'Dutch Carbon Budget'!$D$39 -> 15.727728 | F27: Per current emissions | G27: =G11*'Dutch Carbon Budget'!$D$39 -> 2.8324695 | H27: =H11*'Dutch Carbon Budget'!$D$39 -> 8.4974086 | I27: =I11*'Dutch Carbon Budget'!$D$39 -> 16.994817
A28: Per current economic output | B28: =B12*'Dutch Carbon Budget'!$D$39 -> 6.28158 | C28: =C12*'Dutch Carbon Budget'!$D$39 -> 18.84474 | D28: =D12*'Dutch Carbon Budget'!$D$39 -> 37.68948 | F28: Per current economic output | G28: =G12*'Dutch Carbon Budget'!$D$39 -> 6.7876496 | H28: =H12*'Dutch Carbon Budget'!$D$39 -> 20.362949 | I28: =I12*'Dutch Carbon Budget'!$D$39 -> 40.725898
A29: 2023 | F29: 2023
A30: assuming only 38.5% of CB can be used for housing | F30: assuming only 38.5% of CB can be used for housing
B31: 1,5ºC | C31: 1,7ºC | D31: 2,0ºC | G31: 1,5ºC | H31: 1,7ºC | I31: 2,0ºC
A32: Per capita adjusted by cumulative historic emissions | B32: =B16*'Dutch Carbon Budget'!$D$39 -> -37.153979 | C32: =C16*'Dutch Carbon Budget'!$D$39 -> -33.85399 | D32: =D16*'Dutch Carbon Budget'!$D$39 -> -28.904006 | F32: Per capita adjusted by cumulative historic emissions | G32: =G16*'Dutch Carbon Budget'!$D$39 -> -40.221998 | H32: =H16*'Dutch Carbon Budget'!$D$39 -> -36.64951 | I32: =I16*'Dutch Carbon Budget'!$D$39 -> -31.290778
A33: Per capita | B33: =B17*'Dutch Carbon Budget'!$D$39 -> 1.6499945 | C33: =C17*'Dutch Carbon Budget'!$D$39 -> 4.9499835 | D33: =D17*'Dutch Carbon Budget'!$D$39 -> 9.8999671 | F33: Per capita | G33: =G17*'Dutch Carbon Budget'!$D$39 -> 1.7862441 | H33: =H17*'Dutch Carbon Budget'!$D$39 -> 5.3587324 | I33: =I17*'Dutch Carbon Budget'!$D$39 -> 10.717465
A34: Per current emissions | B34: =B18*'Dutch Carbon Budget'!$D$39 -> 3.0161481 | C34: =C18*'Dutch Carbon Budget'!$D$39 -> 9.0484444 | D34: =D18*'Dutch Carbon Budget'!$D$39 -> 18.096889 | F34: Per current emissions | G34: =G18*'Dutch Carbon Budget'!$D$39 -> 3.265209 | H34: =H18*'Dutch Carbon Budget'!$D$39 -> 9.7956269 | I34: =I18*'Dutch Carbon Budget'!$D$39 -> 19.591254
A35: Per current economic output | B35: =B19*'Dutch Carbon Budget'!$D$39 -> 7.2278118 | C35: =C19*'Dutch Carbon Budget'!$D$39 -> 21.683435 | D35: =D19*'Dutch Carbon Budget'!$D$39 -> 43.366871 | F35: Per current economic output | G35: =G19*'Dutch Carbon Budget'!$D$39 -> 7.8246541 | H35: =H19*'Dutch Carbon Budget'!$D$39 -> 23.473962 | I35: =I19*'Dutch Carbon Budget'!$D$39 -> 46.947925
B37: t CO2 per cap
A38: 2019 | B38: 4.8210977
A39: 2020
A40: 2021
A41: 2022
A42: 2023 | B42: 4.1899418
A43: 2024
A44: 2025
A45: 2026
...
