Workbook

Sheet Content
A1: Journal of Industrial Ecology – www.wileyonlinelibrary.com/journal/jie
A3: SUPPORTING INFORMATION FOR:
A5: van Oorschot, J., Sprecher, B., Rijken, B., Witteveen, P., Blok, M., Schouten, N. & van der Voet, E. Towards a low carbon and circular building sector: Building strategies and urbanization pathways for the Netherlands. Journal of Industrial Ecology.
A8: This supporting information provides material intensity data, recycling data, material stock and flow results, and impact data used for GHG emission and land-use calculations.
A12: Supporting Information 2 (S2)
A13: Content
A14: S2-1 | B14: Methods: Material intensity data
A15: S2-2 | B15: Methods: LCI data
A16: S2-3 | B16: Results: Recycling rate (RR) and Maximum recycled content (MRC) values
A17: S2-4 | B17: Results: stocks and flows
A18: S2-5 | B18: Results: GHG emssions and land use
A19: S2-6 | B19: Discussion: Sensitivity analysis: recycling rates

Sheet meta
A1: Title: | B1: Material content intensity of existing and new buildings (kg/m2)
A2: Source: | B2: Oorschot et al. 2023
A3: doi: | B3: https://doi.org/10.1111/jiec.13375
A4: Empirical Source: | B4: Arnoldussen, J., Errami, S., Semenov, R., Roemers, G., Blok, M., Kamps, M., & Faes, K. (2019). Materiaalstromen, milieu-impact en energieverbruik in de woning- en utiliteitsbouw. Uitgangssituatie en doorkijk naar 2030. https://circulairebouweconomie.nl/wp-content/uploads/2020/02/Rapport-Materiaalstromen-in-de-woning-en-utiliteitsbouw-klein.pdf
A5: Temporal Scope: | B5: pre-1945 to 2050
A6: Geographical Scope: | B6: NL
A7: Unit: | B7: kg/m2 useful floor area

Sheet mi_pre2018
A1: Building type | B1: Cohort | C1: Steel | D1: Copper | E1: Aluminum | F1: Other metals | G1: Wood | H1: Concrete | I1: Brick | J1: Other construction materials | K1: Glass | L1: Ceramics | M1: Plastic | N1: Insulation | O1: Other
C2: kg/m2 UFA | D2: kg/m2 UFA | E2: kg/m2 UFA | F2: kg/m2 UFA | G2: kg/m2 UFA | H2: kg/m2 UFA | I2: kg/m2 UFA | J2: kg/m2 UFA | K2: kg/m2 UFA | L2: kg/m2 UFA | M2: kg/m2 UFA | N2: kg/m2 UFA | O2: kg/m2 UFA
A3: detached (vrijstaand) | B3: pre 1945 | C3: 64.536322 | D3: 0.88389121 | E3: 0.15058813 | F3: 2.6386157 | G3: 134.59223 | H3: 1382.6945 | I3: 306.15154 | J3: 361.4761 | K3: 0.090275356 | L3: 18.528318 | M3: 1.281912 | N3: 13.977079 | O3: 1.5863529
B4: 1946-1974 | C4: {=(25/30)*MI_2018!C4:O4+(5/30)*MI_2018!C5:O5} -> 58.195909 | D4: 0.88389121 | E4: 0.24335574 | F4: 2.6610961 | G4: 67.379139 | H4: 1443.4427 | I4: 275.53638 | J4: 453.40153 | K4: 3.3223657 | L4: 15.912624 | M4: 1.6021925 | N4: 14.553683 | O4: 1.9276527
B5: 1975-2005 | C5: {=(25/30)*MI_2018!C5:O5+(5/30)*MI_2018!C6:O6} -> 53.760244 | D5: 0.88389121 | E5: 0.22328286 | F5: 2.6610961 | G5: 28.888637 | H5: 1450.3671 | I5: 122.46061 | J5: 766.16843 | K5: 5.6310016 | L5: 2.8341529 | M5: 1.8005107 | N5: 15.194186 | O5: 1.9343643
B6: 2006-2022 | C6: 53.747728 | D6: 0.88389121 | E6: 0.22328286 | F6: 2.6610961 | G6: 39.052214 | H6: 1450.3671 | I6: 122.46061 | J6: 766.16843 | K6: 5.6310016 | L6: 2.8341529 | M6: 1.8005107 | N6: 16.061438 | O6: 2.0107569
A7: row house (tussenwoning) | B7: pre 1945 | C7: 51.236411 | D7: 0.3514936 | E7: 0.37854946 | F7: 1.469714 | G7: 64.768413 | H7: 1144.3173 | I7: 162.86606 | J7: 297.16811 | K7: 0.23043419 | L7: 2.7625527 | M7: 0.81826994 | N7: 13.219223 | O7: 1.3741256
B8: 1946-1974 | C8: {=(25/30)*MI_2018!C8:O8+(5/30)*MI_2018!C9:O9} -> 53.458639 | D8: 0.3514936 | E8: 0.45919951 | F8: 1.5202925 | G8: 37.434904 | H8: 1238.7901 | I8: 146.57946 | J8: 333.6555 | K8: 2.6610481 | L8: 2.7625527 | M8: 1.2663895 | N8: 13.538303 | O8: 1.9604835
B9: 1975-2005 | C9: {=(25/30)*MI_2018!C9:O9+(5/30)*MI_2018!C10:O10} -> 54.822602 | D9: 0.3514936 | E9: 0.37808582 | F9: 1.5202925 | G9: 22.392487 | H9: 1304.4812 | I9: 65.146426 | J9: 470.94709 | K9: 4.3972009 | L9: 2.7625527 | M9: 1.871411 | N9: 13.953603 | O9: 1.9730191
B10: 2006-2022 | C10: 54.810217 | D10: 0.3514936 | E10: 0.37808582 | F10: 1.5202925 | G10: 32.834915 | H10: 1304.4812 | I10: 65.146426 | J10: 470.94709 | K10: 4.3972009 | L10: 2.7625527 | M10: 1.871411 | N10: 14.505308 | O10: 2.0533811
A11: shop | B11: pre 1945 | C11: 46.466515 | D11: 0.20715254 | E11: 0.11701019 | F11: 0.46113915 | G11: 42.832492 | H11: 1097.8571 | I11: 171.36517 | J11: 275.99688 | K11: 11.018225 | L11: 18.818937 | M11: 1.4989691 | N11: 16.883191 | O11: 2.010927
B12: 1946-1974 | C12: {=(25/30)*MI_2018!C12:O12+(5/30)*MI_2018!C13:O13} -> 46.813977 | D12: 0.20721356 | E12: 0.3543056 | F12: 0.4949922 | G12: 21.920455 | H12: 1175.5815 | I12: 154.22866 | J12: 290.47608 | K12: 14.681625 | L12: 16.489943 | M12: 1.7784211 | N12: 16.398045 | O12: 3.1644152
B13: 1975-2005 | C13: {=(25/30)*MI_2018!C13:O13+(5/30)*MI_2018!C14:O14} -> 48.051661 | D13: 0.20751864 | E13: 1.4716251 | F13: 0.4949922 | G13: 10.256356 | H13: 1208.6321 | I13: 68.546069 | J13: 363.12482 | K13: 17.29834 | L13: 4.8449722 | M13: 1.8114522 | N13: 11.606467 | O13: 3.1290037
B14: 2006-2022 | C14: 48.035462 | D14: 0.20751864 | E14: 1.4716251 | F14: 0.4949922 | G14: 14.176483 | H14: 1208.6321 | I14: 68.546069 | J14: 363.12482 | K14: 17.29834 | L14: 4.8449722 | M14: 1.8114522 | N14: 7.8462588 | O14: 3.1135821
A15: multiple fam (meergezins) | B15: pre 1945 | C15: 63.247574 | D15: 0.28948118 | E15: 0.18861373 | F15: 0.67728006 | G15: 45.8056 | H15: 1191.0069 | I15: 117.82557 | J15: 235.38274 | K15: 0.8534112 | L15: 5.7025354 | M15: 1.0111191 | N15: 19.453145 | O15: 1.977803
B16: 1946-1974 | C16: {=(25/30)*MI_2018!C16:O16+(5/30)*MI_2018!C17:O17} -> 65.670949 | D16: 0.28948118 | E16: 1.319518 | F16: 0.67814006 | G16: 24.518831 | H16: 1336.5841 | I16: 101.91568 | J16: 225.65258 | K16: 4.6697647 | L16: 5.6751515 | M16: 1.4505484 | N16: 18.950573 | O16: 4.6279342
B17: 1975-2005 | C17: {=(25/30)*MI_2018!C17:O17+(5/30)*MI_2018!C18:O18} -> 78.146748 | D17: 0.28948118 | E17: 6.9569849 | F17: 0.68244004 | G17: 9.8615795 | H17: 1591.1174 | I17: 22.366258 | J17: 177.65654 | K17: 7.3957314 | L17: 5.5382321 | M17: 2.0721547 | N17: 12.964776 | O17: 4.7904671
B18: 2006-2022 | C18: 78.130278 | D18: 0.28948118 | E18: 6.9569849 | F18: 0.68244004 | G18: 9.8615795 | H18: 1591.1174 | I18: 22.366258 | J18: 177.65654 | K18: 7.3957314 | L18: 5.5382321 | M18: 2.0721547 | N18: 7.9364855 | O18: 4.7254553
A19: office | B19: pre 1945 | C19: 73.961059 | D19: 0.33846705 | E19: 0.098316514 | F19: 0.77648306 | G19: 49.785507 | H19: 920.82528 | I19: 86.539152 | J19: 304.47309 | K19: 1.6636304 | L19: 5.2831197 | M19: 1.3213307 | N19: 19.886053 | O19: 2.1094657
B20: 1946-1974 | C20: {=(25/30)*MI_2018!C20:O20+(5/30)*MI_2018!C21:O21} -> 76.434134 | D20: 0.33846705 | E20: 1.2623581 | F20: 0.77797777 | G20: 21.658335 | H20: 1032.307 | I20: 78.580251 | J20: 302.45388 | K20: 5.8367979 | L20: 5.2831197 | M20: 1.691792 | N20: 19.97587 | O20: 2.044295
B21: 1975-2005 | C21: {=(25/30)*MI_2018!C21:O21+(5/30)*MI_2018!C22:O22} -> 88.380354 | D21: 0.33846705 | E21: 7.1459152 | F21: 0.78545131 | G21: 3.1591019 | H21: 1301.4637 | I21: 38.785746 | J21: 292.35783 | K21: 8.8176319 | L21: 5.2831197 | M21: 1.7773784 | N21: 14.902099 | O21: 2.1939223
B22: 2006-2022 | C22: 88.364031 | D22: 0.33846705 | E22: 7.1459152 | F22: 0.78545131 | G22: 3.1591019 | H22: 1301.4637 | I22: 38.785746 | J22: 292.35783 | K22: 8.8176319 | L22: 5.2831197 | M22: 1.7773784 | N22: 11.48879 | O22: 2.1294872
A23: industry | B23: pre 1945 | C23: 92.106594 | D23: 0.24424686 | E23: 0.12761051 | F23: 0.18228376 | G23: 77.515276 | H23: 816.66962 | I23: 10.018768 | J23: 39.883714 | K23: 0.079699212 | L23: 0.19992888 | M23: 1.8818544 | N23: 12.388943 | O23: 0.396484
B24: 1946-1974 | C24: {=(25/30)*MI_2018!C24:O24+(5/30)*MI_2018!C25:O25} -> 84.968425 | D24: 0.24424686 | E24: 0.19278973 | F24: 0.18228679 | G24: 32.731022 | H24: 816.74155 | I24: 9.0196439 | J24: 41.714067 | K24: 0.59011594 | L24: 0.19992888 | M24: 2.114923 | N24: 16.396465 | O24: 0.37791462
B25: 1975-2005 | C25: {=(25/30)*MI_2018!C25:O25+(5/30)*MI_2018!C26:O26} -> 80.172771 | D25: 0.24424686 | E25: 0.44696519 | F25: 0.18230195 | G25: 0.80942498 | H25: 819.2532 | I25: 4.0240254 | J25: 50.865835 | K25: 0.95469932 | L25: 0.19992888 | M25: 2.1069969 | N25: 22.017761 | O25: 0.31221954
B26: 2006-2022 | C26: 80.171315 | D26: 0.24424686 | E26: 0.44696519 | F26: 0.18230195 | G26: 0.80942498 | H26: 819.2532 | I26: 4.0240254 | J26: 50.865835 | K26: 0.95469932 | L26: 0.19992888 | M26: 2.1069969 | N26: 31.163158 | O26: 0.30647138
A27: services | B27: pre 1945 | C27: 76.371624 | D27: 0.32171695 | E27: 0.10965742 | F27: 0.75362734 | G27: 56.616517 | H27: 1244.4586 | I27: 141.54174 | J27: 228.63563 | K27: 0.81073296 | L27: 12.265441 | M27: 1.1337826 | N27: 17.710761 | O27: 2.0345577
B28: 1946-1974 | C28: {=(25/30)*MI_2018!C28:O28+(5/30)*MI_2018!C29:O29} -> 76.069464 | D28: 0.32188913 | E28: 1.1115106 | F28: 0.76766215 | G28: 27.060948 | H28: 1329.1327 | I28: 127.38757 | J28: 245.01502 | K28: 2.8722794 | L28: 11.197326 | M28: 1.3916081 | N28: 17.42263 | O28: 3.2508216
B29: 1975-2005 | C29: {=(25/30)*MI_2018!C29:O29+(5/30)*MI_2018!C30:O30} -> 77.420476 | D29: 0.32275004 | E29: 6.1419789 | F29: 0.77157026 | G29: 6.3171164 | H29: 1378.8948 | I29: 56.616698 | J29: 326.912 | K29: 4.1439176 | L29: 5.8567494 | M29: 1.6670462 | N29: 12.921936 | O29: 3.1764031
B30: 2006-2022 | C30: 77.420896 | D30: 0.32275004 | E30: 6.1419789 | F30: 0.77157026 | G30: 7.4154302 | H30: 1378.8948 | I30: 56.616698 | J30: 326.912 | K30: 4.4154544 | L30: 5.8567494 | M30: 1.6713908 | N30: 8.9234627 | O30: 3.1264976

Sheet MI_2018
A1: Building type | B1: Cohort | C1: Steel | D1: Copper | E1: Aluminum | F1: Other metals | G1: Wood | H1: Concrete | I1: Brick | J1: Other construction materials | K1: Glass | L1: Ceramics | M1: Plastic | N1: Insulation | O1: Other
C2: kg/m2 UFA | D2: kg/m2 UFA | E2: kg/m2 UFA | F2: kg/m2 UFA | G2: kg/m2 UFA | H2: kg/m2 UFA | I2: kg/m2 UFA | J2: kg/m2 UFA | K2: kg/m2 UFA | L2: kg/m2 UFA | M2: kg/m2 UFA | N2: kg/m2 UFA | O2: kg/m2 UFA
A3: detached house | B3: <1945 | C3: 64.536322 | D3: 0.88389121 | E3: 0.15058813 | F3: 2.6386157 | G3: 134.59223 | H3: 1382.6945 | I3: 306.15154 | J3: 361.4761 | K3: 0.090275356 | L3: 18.528318 | M3: 1.281912 | N3: 13.977079 | O3: 1.5863529
B4: 1945-1970 | C4: 59.082541 | D4: 0.88389121 | E4: 0.24737031 | F4: 2.6610961 | G4: 75.483783 | H4: 1442.0578 | I4: 306.15154 | J4: 390.84815 | K4: 2.8606385 | L4: 18.528318 | M4: 1.5625289 | N4: 14.460272 | O4: 1.929366
B5: 1970-2000 | C5: 53.762747 | D5: 0.88389121 | E5: 0.22328286 | F5: 2.6610961 | G5: 26.855921 | H5: 1450.3671 | I5: 122.46061 | J5: 766.16843 | K5: 5.6310016 | L5: 2.8341529 | M5: 1.8005107 | N5: 15.020736 | O5: 1.9190858
B6: 2000-2018 | C6: 53.747728 | D6: 0.88389121 | E6: 0.22328286 | F6: 2.6610961 | G6: 39.052214 | H6: 1450.3671 | I6: 122.46061 | J6: 766.16843 | K6: 5.6310016 | L6: 2.8341529 | M6: 1.8005107 | N6: 16.061438 | O6: 2.0107569
A7: row house | B7: <1945 | C7: 51.236411 | D7: 0.3514936 | E7: 0.37854946 | F7: 1.469714 | G7: 64.768413 | H7: 1144.3173 | I7: 162.86606 | J7: 297.16811 | K7: 0.23043419 | L7: 2.7625527 | M7: 0.81826994 | N7: 13.219223 | O7: 1.3741256
B8: 1945-1970 | C8: 53.185351 | D8: 0.3514936 | E8: 0.47542225 | F8: 1.5202925 | G8: 40.861085 | H8: 1225.6518 | I8: 162.86606 | J8: 306.19718 | K8: 2.3138175 | L8: 2.7625527 | M8: 1.1453852 | N8: 13.477311 | O8: 1.9611909
B9: 1970-2000 | C9: 54.825079 | D9: 0.3514936 | E9: 0.37808582 | F9: 1.5202925 | G9: 20.304001 | H9: 1304.4812 | I9: 65.146426 | J9: 470.94709 | K9: 4.3972009 | L9: 2.7625527 | M9: 1.871411 | N9: 13.843262 | O9: 1.9569467
B10: 2000-2018 | C10: 54.810217 | D10: 0.3514936 | E10: 0.37808582 | F10: 1.5202925 | G10: 32.834915 | H10: 1304.4812 | I10: 65.146426 | J10: 470.94709 | K10: 4.3972009 | L10: 2.7625527 | M10: 1.871411 | N10: 14.505308 | O10: 2.0533811
A11: shop | B11: <1945 | C11: 46.466515 | D11: 0.20715254 | E11: 0.11701019 | F11: 0.46113915 | G11: 42.832492 | H11: 1097.8571 | I11: 171.36517 | J11: 275.99688 | K11: 11.018225 | L11: 18.818937 | M11: 1.4989691 | N11: 16.883191 | O11: 2.010927
B12: 1945-1970 | C12: 46.565792 | D12: 0.20715254 | E12: 0.1308417 | F12: 0.4949922 | G12: 24.410079 | H12: 1168.9714 | I12: 171.36517 | J12: 275.94633 | K12: 14.158282 | L12: 18.818937 | M12: 1.7718149 | N12: 17.205953 | O12: 3.1708806
B13: 1970-2000 | C13: 48.054901 | D13: 0.20751864 | E13: 1.4716251 | F13: 0.4949922 | G13: 9.4723306 | H13: 1208.6321 | I13: 68.546069 | J13: 363.12482 | K13: 17.29834 | L13: 4.8449722 | M13: 1.8114522 | N13: 12.358509 | O13: 3.132088
B14: 2000-2018 | C14: 48.035462 | D14: 0.20751864 | E14: 1.4716251 | F14: 0.4949922 | G14: 14.176483 | H14: 1208.6321 | I14: 68.546069 | J14: 363.12482 | K14: 17.29834 | L14: 4.8449722 | M14: 1.8114522 | N14: 7.8462588 | O14: 3.1135821
A15: apartment | B15: <1945 | C15: 63.247574 | D15: 0.28948118 | E15: 0.18861373 | F15: 0.67728006 | G15: 45.8056 | H15: 1191.0069 | I15: 117.82557 | J15: 235.38274 | K15: 0.8534112 | L15: 5.7025354 | M15: 1.0111191 | N15: 19.453145 | O15: 1.977803
B16: 1945-1970 | C16: 63.175131 | D16: 0.28948118 | E16: 0.19202466 | F16: 0.67728006 | G16: 27.450282 | H16: 1285.6774 | I16: 117.82557 | J16: 235.25179 | K16: 4.1245713 | L16: 5.7025354 | M16: 1.3262272 | N16: 19.946601 | O16: 4.5928272
B17: 1970-2000 | C17: 78.150042 | D17: 0.28948118 | E17: 6.9569849 | F17: 0.68244004 | G17: 9.8615795 | H17: 1591.1174 | I17: 22.366258 | J17: 177.65654 | K17: 7.3957314 | L17: 5.5382321 | M17: 2.0721547 | N17: 13.970435 | O17: 4.8034694
B18: 2000-2018 | C18: 78.130278 | D18: 0.28948118 | E18: 6.9569849 | F18: 0.68244004 | G18: 9.8615795 | H18: 1591.1174 | I18: 22.366258 | J18: 177.65654 | K18: 7.3957314 | L18: 5.5382321 | M18: 2.0721547 | N18: 7.9364855 | O18: 4.7254553
A19: office | B19: <1945 | C19: 73.961059 | D19: 0.33846705 | E19: 0.098316514 | F19: 0.77648306 | G19: 49.785507 | H19: 920.82528 | I19: 86.539152 | J19: 304.47309 | K19: 1.6636304 | L19: 5.2831197 | M19: 1.3213307 | N19: 19.886053 | O19: 2.1094657
B20: 1945-1970 | C20: 74.044237 | D20: 0.33846705 | E20: 0.085646642 | F20: 0.77648306 | G20: 25.358182 | H20: 978.47563 | I20: 86.539152 | J20: 304.47309 | K20: 5.2406312 | L20: 5.2831197 | M20: 1.6746748 | N20: 20.854092 | O20: 2.0117921
B21: 1970-2000 | C21: 88.383619 | D21: 0.33846705 | E21: 7.1459152 | F21: 0.78545131 | G21: 3.1591019 | H21: 1301.4637 | I21: 38.785746 | J21: 292.35783 | K21: 8.8176319 | L21: 5.2831197 | M21: 1.7773784 | N21: 15.58476 | O21: 2.2068094
B22: 2000-2018 | C22: 88.364031 | D22: 0.33846705 | E22: 7.1459152 | F22: 0.78545131 | G22: 3.1591019 | H22: 1301.4637 | I22: 38.785746 | J22: 292.35783 | K22: 8.8176319 | L22: 5.2831197 | M22: 1.7773784 | N22: 11.48879 | O22: 2.1294872
A23: industry | B23: <1945 | C23: 92.106594 | D23: 0.24424686 | E23: 0.12761051 | F23: 0.18228376 | G23: 77.515276 | H23: 816.66962 | I23: 10.018768 | J23: 39.883714 | K23: 0.079699212 | L23: 0.19992888 | M23: 1.8818544 | N23: 12.388943 | O23: 0.396484
B24: 1945-1970 | C24: 85.927497 | D24: 0.24424686 | E24: 0.14195464 | F24: 0.18228376 | G24: 39.115341 | H24: 816.23921 | I24: 10.018768 | J24: 39.883714 | K24: 0.51719926 | L24: 0.19992888 | M24: 2.1165082 | N24: 15.638021 | O24: 0.39082371
B25: 1970-2000 | C25: 80.173062 | D25: 0.24424686 | E25: 0.44696519 | F25: 0.18230195 | G25: 0.80942498 | H25: 819.2532 | I25: 4.0240254 | J25: 50.865835 | K25: 0.95469932 | L25: 0.19992888 | M25: 2.1069969 | N25: 20.188682 | O25: 0.31336917
B26: 2000-2018 | C26: 80.171315 | D26: 0.24424686 | E26: 0.44696519 | F26: 0.18230195 | G26: 0.80942498 | H26: 819.2532 | I26: 4.0240254 | J26: 50.865835 | K26: 0.95469932 | L26: 0.19992888 | M26: 2.1069969 | N26: 31.163158 | O26: 0.30647138
A27: services | B27: <1945 | C27: 76.371624 | D27: 0.32171695 | E27: 0.10965742 | F27: 0.75362734 | G27: 56.616517 | H27: 1244.4586 | I27: 141.54174 | J27: 228.63563 | K27: 0.81073296 | L27: 12.265441 | M27: 1.1337826 | N27: 17.710761 | O27: 2.0345577
B28: 1945-1970 | C28: 75.799279 | D28: 0.32171695 | E28: 0.10541698 | F28: 0.76688053 | G28: 31.253646 | H28: 1319.1803 | I28: 141.54174 | J28: 228.63563 | K28: 2.6288133 | L28: 12.265441 | M28: 1.3366943 | N28: 18.16283 | O28: 3.263709
B29: 1970-2000 | C29: 77.420392 | D29: 0.32275004 | E29: 6.1419789 | F29: 0.77157026 | G29: 6.0974537 | H29: 1378.8948 | I29: 56.616698 | J29: 326.912 | K29: 4.0896102 | L29: 5.8567494 | M29: 1.6661773 | N29: 13.72163 | O29: 3.1863842
B30: 2000-2018 | C30: 77.420896 | D30: 0.32275004 | E30: 6.1419789 | F30: 0.77157026 | G30: 7.4154302 | H30: 1378.8948 | I30: 56.616698 | J30: 326.912 | K30: 4.4154544 | L30: 5.8567494 | M30: 1.6713908 | N30: 8.9234627 | O30: 3.1264976

Sheet MI_2018-2050
A1: Conventional | B1: Aluminum | C1: Clay brick | D1: Concrete | E1: Bitumen | F1: Electronics | G1: Gypsum | H1: Glass | I1: Wood | J1: Insulation | K1: Sand-lime brick | L1: Ceramics | M1: Copper | N1: Plastics | O1: Adhesives & paint | P1: Mortal | Q1: Other biobased materials | R1: Other metals | S1: Paper | T1: Iron & steel | U1: Stone | V1: Sand
B2: kg/m2 UFA | C2: kg/m2 UFA | D2: kg/m2 UFA | E2: kg/m2 UFA | F2: kg/m2 UFA | G2: kg/m2 UFA | H2: kg/m2 UFA | I2: kg/m2 UFA | J2: kg/m2 UFA | K2: kg/m2 UFA | L2: kg/m2 UFA | M2: kg/m2 UFA | N2: kg/m2 UFA | O2: kg/m2 UFA | P2: kg/m2 UFA | Q2: kg/m2 UFA | R2: kg/m2 UFA | S2: kg/m2 UFA | T2: kg/m2 UFA | U2: kg/m2 UFA | V2: kg/m2 UFA
A3: Row house | B3: 1.1565217 | C3: 143.97295 | D3: 1365.4705 | E3: 0.51400966 | F3: 0.89855072 | G3: 20.342995 | H3: 7.5458937 | I3: 71.697585 | J3: 24.311111 | K3: 0 | L3: 6.5748792 | M3: 0.58454106 | N3: 2.8743961 | O3: 1.4251208 | P3: 51.301449 | Q3: 0.57584541 | R3: 0.11690821 | S3: 0.58454106 | T3: 26.750725 | U3: 0.096618357 | V3: 128.72947
A4: Detached house | B4: 1.7492537 | C4: 174.73433 | D4: 982.04478 | E4: 0.08358209 | F4: 0.62686567 | G4: 26.716418 | H4: 11.134328 | I4: 81.029851 | J4: 31.671642 | K4: 0 | L4: 5.358209 | M4: 0.47761194 | N4: 2.3731343 | O4: 1.5044776 | P4: 66.677612 | Q4: 0.51044776 | R4: 0.11940299 | S4: 1.3731343 | T4: 22.758209 | U4: 0.044776119 | V4: 99.507463
A5: Apartment | B5: 1.398913 | C5: 189.65217 | D5: 894.05109 | E5: 0.25217391 | F5: 1.2880435 | G5: 32.126087 | H5: 5.8913043 | I5: 41.842391 | J5: 6.773913 | K5: 0 | L5: 12.581522 | M5: 0.375 | N5: 2.548913 | O5: 1.1652174 | P5: 50.107609 | Q5: 0.10978261 | R5: 0.11956522 | S5: 0.27173913 | T5: 18.523913 | U5: 0.5326087 | V5: 30.11413
A6: Office | B6: 2.2051661 | C6: 20.758672 | D6: 884.30369 | E6: 0.27453875 | F6: 2.0767528 | G6: 9.1505535 | H6: 10.588561 | I6: 32.629151 | J6: 6.4638376 | K6: 0 | L6: 0.83579336 | M6: 0.088560886 | N6: 2.0512915 | O6: 0.62324723 | P6: 9.7760148 | Q6: 0.11845018 | R6: 0.091881919 | S6: 0.07195572 | T6: 25.561993 | U6: 0.055350554 | V6: 37.400369
A7: Industry | B7: 0.16122449 | C7: 3.377551 | D7: 663.9449 | E7: 0 | F7: 0.051020408 | G7: 0.66122449 | H7: 0.13265306 | I7: 28.320408 | J7: 53.346939 | K7: 13.044898 | L7: 0.15306122 | M7: 0.23469388 | N7: 1.1326531 | O7: 0.14285714 | P7: 1.4183673 | Q7: 0 | R7: 0.1122449 | S7: 0 | T7: 67.002041 | U7: 0.010204082 | V7: 19.622449
A8: Services | B8: 6.4113786 | C8: 55.317287 | D8: 1082.954 | E8: 0.32275711 | F8: 0.071115974 | G8: 31.415755 | H8: 4.6608315 | I8: 29.66302 | J8: 11.871991 | K8: 222.75711 | L8: 5.9956236 | M8: 0.31728665 | N8: 1.3205689 | O8: 2.7275711 | P8: 23.741794 | Q8: 0 | R8: 0.74507659 | S8: 0.087527352 | T8: 70.103939 | U8: 0.37199125 | V8: 12.871991
A9: Shop | B9: 1.1846154 | C9: 68.549451 | D9: 1006.7033 | E9: 0 | F9: 0.032967033 | G9: 21.320879 | H9: 17.296703 | I9: 37.008791 | J9: 9.5802198 | K9: 271.14725 | L9: 5.2527473 | M9: 0.20879121 | N9: 1.8021978 | O9: 2.5318681 | P9: 30.505495 | Q9: 1.2307692 | R9: 0.48791209 | S9: 0.42857143 | T9: 41.303297 | U9: 0.087912088 | V9: 13.505495
A11: Biobased | B11: Aluminum | C11: Clay brick | D11: Concrete | E11: Bitumen | F11: Electronics | G11: Gypsum | H11: Glass | I11: Wood | J11: Insulation | K11: Sand-lime brick | L11: Ceramics | M11: Copper | N11: Plastics | O11: Adhesives & paint | P11: Mortal | Q11: Other biobased materials | R11: Other metals | S11: Paper | T11: Iron & steel | U11: Stone | V11: Sand
B12: kg/m2 UFA | C12: kg/m2 UFA | D12: kg/m2 UFA | E12: kg/m2 UFA | F12: kg/m2 UFA | G12: kg/m2 UFA | H12: kg/m2 UFA | I12: kg/m2 UFA | J12: kg/m2 UFA | K12: kg/m2 UFA | L12: kg/m2 UFA | M12: kg/m2 UFA | N12: kg/m2 UFA | O12: kg/m2 UFA | P12: kg/m2 UFA | Q12: kg/m2 UFA | R12: kg/m2 UFA | S12: kg/m2 UFA | T12: kg/m2 UFA | U12: kg/m2 UFA | V12: kg/m2 UFA
A13: Row house | B13: 1.0318841 | C13: 35.993237 | D13: 474.01256 | E13: 0.12850242 | F13: 0.89855072 | G13: 40.748792 | H13: 7.5458937 | I13: 212.08019 | J13: 17.998068 | K13: 0 | L13: 6.5748792 | M13: 0.58454106 | N13: 2.8743961 | O13: 3.3381643 | P13: 14.394203 | Q13: 2.3033816 | R13: 0.10531401 | S13: 0.58454106 | T13: 17.437681 | U13: 0.096618357 | V13: 128.72947
A14: Detached house | B14: 1.5791045 | C14: 43.683582 | D14: 357.01493 | E14: 0.020895522 | F14: 0.62686567 | G14: 59.402985 | H14: 11.134328 | I14: 221.13433 | J14: 24.373134 | K14: 0 | L14: 5.358209 | M14: 0.47761194 | N14: 2.2835821 | O14: 3.241791 | P14: 17.979104 | Q14: 2.041791 | R14: 0.11940299 | S14: 1.3731343 | T14: 13.973134 | U14: 0.044776119 | V14: 99.507463
A15: Apartment | B15: 0.94891304 | C15: 47.413043 | D15: 252.48152 | E15: 0.063043478 | F15: 1.2880435 | G15: 35.879348 | H15: 5.8913043 | I15: 160.75 | J15: 3.976087 | K15: 0 | L15: 12.581522 | M15: 0.375 | N15: 2.6793478 | O15: 1.6771739 | P15: 15.832609 | Q15: 0.43913043 | R15: 0.10326087 | S15: 0.27173913 | T15: 9.073913 | U15: 0.5326087 | V15: 30.11413
A16: Office | B16: 1.4479705 | C16: 5.1896679 | D16: 283.63173 | E16: 0.068634686 | F16: 2.2129151 | G16: 11.893727 | H16: 10.588561 | I16: 126.58118 | J16: 4.0859779 | K16: 0 | L16: 0.83579336 | M16: 0.088560886 | N16: 2.0446494 | O16: 1.2476015 | P16: 2.6225092 | Q16: 0.47380074 | R16: 0.068634686 | S16: 0.07195572 | T16: 14.805166 | U16: 0.055350554 | V16: 37.400369
A17: Industry | B17: 0.1244898 | C17: 3.377551 | D17: 248.61633 | E17: 0 | F17: 0.051020408 | G17: 1.3285714 | H17: 0.13265306 | I17: 101.74082 | J17: 53.377551 | K17: 3.2612245 | L17: 0.15306122 | M17: 0.23469388 | N17: 1.1326531 | O17: 0.14285714 | P17: 1.4183673 | Q17: 0 | R17: 0.1122449 | S17: 0 | T17: 34.191837 | U17: 0.010204082 | V17: 19.622449
A18: Services | B18: 1.6356674 | C18: 55.317287 | D18: 531.64661 | E18: 0.32275711 | F18: 0.071115974 | G18: 70.028446 | H18: 4.6608315 | I18: 92.328228 | J18: 12.810722 | K18: 55.689278 | L18: 5.9956236 | M18: 0.31728665 | N18: 1.2450766 | O18: 2.0809628 | P18: 23.741794 | Q18: 0 | R18: 0.73194748 | S18: 0.087527352 | T18: 30.2407 | U18: 0.37199125 | V18: 12.871991
A19: Shop | B19: 0.32087912 | C19: 68.549451 | D19: 492.41758 | E19: 0 | F19: 0.032967033 | G19: 52.90989 | H19: 17.296703 | I19: 100.03516 | J19: 10.76044 | K19: 67.786813 | L19: 5.2527473 | M19: 0.20879121 | N19: 1.7692308 | O19: 2.1824176 | P19: 30.505495 | Q19: 1.2307692 | R19: 0.46813187 | S19: 0.42857143 | T19: 21.015385 | U19: 0.087912088 | V19: 13.505495
A21: Circular | B21: Aluminum | C21: Clay brick | D21: Concrete | E21: Bitumen | F21: Electronics | G21: Gypsum | H21: Glass | I21: Wood | J21: Insulation | K21: Sand-lime brick | L21: Ceramics | M21: Copper | N21: Plastics | O21: Adhesives & paint | P21: Mortal | Q21: Other biobased materials | R21: Other metals | S21: Paper | T21: Iron & steel | U21: Stone | V21: Sand
B22: kg/m2 UFA | C22: kg/m2 UFA | D22: kg/m2 UFA | E22: kg/m2 UFA | F22: kg/m2 UFA | G22: kg/m2 UFA | H22: kg/m2 UFA | I22: kg/m2 UFA | J22: kg/m2 UFA | K22: kg/m2 UFA | L22: kg/m2 UFA | M22: kg/m2 UFA | N22: kg/m2 UFA | O22: kg/m2 UFA | P22: kg/m2 UFA | Q22: kg/m2 UFA | R22: kg/m2 UFA | S22: kg/m2 UFA | T22: kg/m2 UFA | U22: kg/m2 UFA | V22: kg/m2 UFA
A23: Row house | B23: 0.99033816 | C23: 115.09662 | D23: 917.90338 | E23: 0.64251208 | F23: 0.89855072 | G23: 3.5845411 | H23: 7.5458937 | I23: 34.193237 | J23: 14.140097 | K23: 0 | L23: 6.5748792 | M23: 0.58454106 | N23: 3.2512077 | O23: 0.55072464 | P23: 2.0917874 | Q23: 0 | R23: 0.12077295 | S23: 0.58454106 | T23: 26.376812 | U23: 0.096618357 | V23: 128.72947
A24: Detached house | B24: 1.4925373 | C24: 159.08955 | D24: 762.50746 | E24: 0.10447761 | F24: 0.62686567 | G24: 2.9253731 | H24: 11.134328 | I24: 32.910448 | J24: 14.641791 | K24: 0 | L24: 5.358209 | M24: 0.47761194 | N24: 2.9253731 | O24: 0.50746269 | P24: 1.7462687 | Q24: 0 | R24: 0.11940299 | S24: 0.53731343 | T24: 26.089552 | U24: 0.044776119 | V24: 99.507463
A25: Apartment | B25: 1.1141304 | C25: 80.217391 | D25: 421.00543 | E25: 0.31521739 | F25: 1.2880435 | G25: 9.3967391 | H25: 5.8913043 | I25: 36.38587 | J25: 5.7663043 | K25: 0 | L25: 12.581522 | M25: 0.375 | N25: 2.798913 | O25: 0.95108696 | P25: 19.418478 | Q25: 0 | R25: 0.125 | S25: 0.57608696 | T25: 18.059783 | U25: 0.5326087 | V25: 30.11413
A26: Office | B26: 1.8819188 | C26: 25.948339 | D26: 458.92804 | E26: 0.34317343 | F26: 2.0313653 | G26: 0.055350554 | H26: 10.588561 | I26: 11.47417 | J26: 5.0369004 | K26: 0 | L26: 0.83579336 | M26: 0.088560886 | N26: 2.2416974 | O26: 0.33763838 | P26: 0.94095941 | Q26: 0 | R26: 0.099630996 | S26: 0.07195572 | T26: 21.896679 | U26: 0.055350554 | V26: 37.400369
A27: Industry | B27: 0.14285714 | C27: 3.377551 | D27: 747.65306 | E27: 0 | F27: 0.051020408 | G27: 0.39795918 | H27: 0.13265306 | I27: 5.7040816 | J27: 53.326531 | K27: 16.306122 | L27: 0.15306122 | M27: 0.23469388 | N27: 1.1326531 | O27: 0.14285714 | P27: 0.020408163 | Q27: 0 | R27: 0.1122449 | S27: 0 | T27: 75.540816 | U27: 0.010204082 | V27: 19.622449
A28: Services | B28: 0.38840263 | C28: 55.317287 | D28: 501.90372 | E28: 0.32275711 | F28: 0.071115974 | G28: 9.928884 | H28: 4.6608315 | I28: 101.46061 | J28: 10.880744 | K28: 238.79103 | L28: 5.9956236 | M28: 0.31728665 | N28: 1.3347921 | O28: 1.7997812 | P28: 0.96280088 | Q28: 0 | R28: 0.73851204 | S28: 0.087527352 | T28: 52.844639 | U28: 0.37199125 | V28: 12.871991
A29: Shop | B29: 0.51648352 | C29: 68.549451 | D29: 404.65934 | E29: 0 | F29: 0.032967033 | G29: 9.5604396 | H29: 17.296703 | I29: 69.241758 | J29: 9.2417582 | K29: 294.17582 | L29: 5.2527473 | M29: 0.20879121 | N29: 1.7912088 | O29: 2 | P29: 2.2747253 | Q29: 1.2307692 | R29: 0.49450549 | S29: 0.42857143 | T29: 19.351648 | U29: 0.087912088 | V29: 13.505495
A32: Baseline (without biobased construction) | B32: Aluminum | C32: Clay brick | D32: Concrete | E32: Bitumen | F32: Electronics | G32: Gypsum | H32: Glass | I32: Wood | J32: Insulation | K32: Sand-lime brick | L32: Ceramics | M32: Copper | N32: Plastics | O32: Adhesives & paint | P32: Mortal | Q32: Other biobased materials | R32: Other metals | S32: Paper | T32: Iron & steel | U32: Stone | V32: Sand
B33: kg/m2 UFA | C33: kg/m2 UFA | D33: kg/m2 UFA | E33: kg/m2 UFA | F33: kg/m2 UFA | G33: kg/m2 UFA | H33: kg/m2 UFA | I33: kg/m2 UFA | J33: kg/m2 UFA | K33: kg/m2 UFA | L33: kg/m2 UFA | M33: kg/m2 UFA | N33: kg/m2 UFA | O33: kg/m2 UFA | P33: kg/m2 UFA | Q33: kg/m2 UFA | R33: kg/m2 UFA | S33: kg/m2 UFA | T33: kg/m2 UFA | U33: kg/m2 UFA | V33: kg/m2 UFA
A34: Row house | B34: 1.1980676 | C34: 179.96618 | D34: 1662.6232 | E34: 0.64251208 | F34: 0.89855072 | G34: 13.541063 | H34: 7.5458937 | I34: 24.903382 | J34: 26.415459 | K34: 0 | L34: 6.5748792 | M34: 0.58454106 | N34: 2.8743961 | O34: 0.78743961 | P34: 63.603865 | Q34: 0 | R34: 0.12077295 | S34: 0.58454106 | T34: 29.855072 | U34: 0.096618357 | V34: 128.72947
A35: Detached house | B35: 1.8059701 | C35: 218.41791 | D35: 1190.3881 | E35: 0.10447761 | F35: 0.62686567 | G35: 15.820896 | H35: 11.134328 | I35: 34.328358 | J35: 34.104478 | K35: 0 | L35: 5.358209 | M35: 0.47761194 | N35: 2.4029851 | O35: 0.92537313 | P35: 82.910448 | Q35: 0 | R35: 0.11940299 | S35: 1.3731343 | T35: 25.686567 | U35: 0.044776119 | V35: 99.507463
A36: Apartment | B36: 1.548913 | C36: 237.06522 | D36: 1107.9076 | E36: 0.31521739 | F36: 1.2880435 | G36: 30.875 | H36: 5.8913043 | I36: 2.2065217 | J36: 7.7065217 | K36: 0 | L36: 12.581522 | M36: 0.375 | N36: 2.5054348 | O36: 0.99456522 | P36: 61.532609 | Q36: 0 | R36: 0.125 | S36: 0.27173913 | T36: 21.673913 | U36: 0.5326087 | V36: 30.11413
A37: Office | B37: 2.4575646 | C37: 25.948339 | D37: 1084.5277 | E37: 0.34317343 | F37: 2.0313653 | G37: 8.2361624 | H37: 10.588561 | I37: 1.3118081 | J37: 7.2564576 | K37: 0 | L37: 0.83579336 | M37: 0.088560886 | N37: 2.0535055 | O37: 0.41512915 | P37: 12.160517 | Q37: 0 | R37: 0.099630996 | S37: 0.07195572 | T37: 29.147601 | U37: 0.055350554 | V37: 37.400369
A38: Industry | B38: 0.17346939 | C38: 3.377551 | D38: 802.38776 | E38: 0 | F38: 0.051020408 | G38: 0.43877551 | H38: 0.13265306 | I38: 3.8469388 | J38: 53.336735 | K38: 16.306122 | L38: 0.15306122 | M38: 0.23469388 | N38: 1.1326531 | O38: 0.14285714 | P38: 1.4183673 | Q38: 0 | R38: 0.1122449 | S38: 0 | T38: 77.938776 | U38: 0.010204082 | V38: 19.622449
A39: Services | B39: 8.0032823 | C39: 55.317287 | D39: 1266.7232 | E39: 0.32275711 | F39: 0.071115974 | G39: 18.544858 | H39: 4.6608315 | I39: 8.7746171 | J39: 11.559081 | K39: 278.44639 | L39: 5.9956236 | M39: 0.31728665 | N39: 1.345733 | O39: 2.9431072 | P39: 23.741794 | Q39: 0 | R39: 0.74945295 | S39: 0.087527352 | T39: 83.391685 | U39: 0.37199125 | V39: 12.871991
A40: Shop | B40: 1.4725275 | C40: 68.549451 | D40: 1178.1319 | E40: 0 | F40: 0.032967033 | G40: 10.791209 | H40: 17.296703 | I40: 16 | J40: 9.1868132 | K40: 338.93407 | L40: 5.2527473 | M40: 0.20879121 | N40: 1.8131868 | O40: 2.6483516 | P40: 30.505495 | Q40: 1.2307692 | R40: 0.49450549 | S40: 0.42857143 | T40: 48.065934 | U40: 0.087912088 | V40: 13.505495

Sheet Share_of_insulation_materials
C1: Glass wool | D1: Expanded polystyrene | E1: Stone wool | F1: Polyurethanes | G1: Extruded polystyrene | H1: Biobased (wooden fibre board or flaxwool )
A2: Stock | C2: 0.37 | D2: 0.27 | E2: 0.22 | F2: 0.08 | G2: 0.06 | I2: Zhang (2021)*, chapter 5, Table A5.5., page 113
A3: Construction | B3: Conventional | C3: 0.37 | D3: 0.27 | E3: 0.22 | F3: 0.08 | G3: 0.06 | I3: Zhang (2021), chapter 5, Table A5.5., page 113 + own assumptions, see main text
B4: Circular | C4: 0.37 | E4: 0.3 | H4: 0.33
B5: Biobased | C5: 0.37 | E5: 0.22 | H5: =0.14+0.27 -> 0.41
A8: Zhang, C. (2021). Towards circular and energy-efficient management of building stock: an analysis of the residential sector of the Netherlands. PhD Thesis at Leiden University, The Netherlands. Chapter 5: Recycling potential in building energy renovation: a prospective study of the Dutch residential building stock up to 2050

Sheet GHG_Primary_production
B1: index | C1: amount | D1: unit | E1: reference product | F1: name | G1: location | H1: database | I1: IPCC 2013 | climate change | GWP 100a | J1: Share | K1: Assumptions
A2: Aluminum | B2: aluminium, primary, ingot | aluminium production, primary, ingot | RoW | kilogram | cutoff38 - Janneke | C2: 1 | D2: kilogram | E2: aluminium, primary, ingot | F2: aluminium production, primary, ingot | G2: RoW | H2: cutoff38 - Janneke | I2: 20.974113
A3: Clay brick | B3: clay brick | clay brick production | RER | kilogram | cutoff38 - Janneke | C3: 1 | D3: kilogram | E3: clay brick | F3: clay brick production | G3: RER | H3: cutoff38 - Janneke | I3: 0.24253743
A4: Concrete | B4: concrete, 30MPa | concrete production 30MPa | RoW | cubic meter | cutoff38 - Janneke | C4: 0.000431779 | D4: cubic meter | E4: concrete, 30MPa | F4: concrete production 30MPa | G4: RoW | H4: cutoff38 - Janneke | I4: 0.11748738 | K4: Concrete density: 2316 kg/m3
A5: Bitumen | B5: bitumen seal | bitumen seal production | RER | kilogram | cutoff38 - Janneke | C5: 1 | D5: kilogram | E5: bitumen seal | F5: bitumen seal production | G5: RER | H5: cutoff38 - Janneke | I5: 1.0763388
A6: Electronics | B6: copper, cathode | copper production, cathode, solvent extraction and electrowinning process | GLO | kilogram | cutoff38 - Janneke | C6: 1 | D6: kilogram | E6: copper, cathode | F6: copper production, cathode, solvent extraction and electrowinning process | G6: GLO | H6: cutoff38 - Janneke | I6: 6.7357284 | J6: 0.5
B7: polyvinylchloride, suspension polymerised | polyvinylchloride production, suspension polymerisation | RER | kilogram | cutoff38 - Janneke | C7: 1 | D7: kilogram | E7: polyvinylchloride, suspension polymerised | F7: polyvinylchloride production, suspension polymerisation | G7: RER | H7: cutoff38 - Janneke | I7: 1.897504 | J7: 0.5
A8: Gypsum | B8: gypsum fibreboard | gypsum fibreboard production | RoW | kilogram | cutoff38 - Janneke | C8: 1 | D8: kilogram | E8: gypsum fibreboard | F8: gypsum fibreboard production | G8: RoW | H8: cutoff38 - Janneke | I8: 0.27401066
A9: Glass | B9: flat glass, uncoated | flat glass production, uncoated | RER | kilogram | cutoff38 - Janneke | C9: 1 | D9: kilogram | E9: flat glass, uncoated | F9: flat glass production, uncoated | G9: RER | H9: cutoff38 - Janneke | I9: 0.96429253
A10: Wood & other biobased materials | B10: sawnwood, beam, softwood, dried (u=20%), planed | planing, beam, softwood, u=20% | Europe without Switzerland | cubic meter | cutoff38 - Janneke | C10: 0.0021929825 | D10: cubic meter | E10: sawnwood, beam, softwood, dried (u=20%), planed | F10: planing, beam, softwood, u=20% | G10: Europe without Switzerland | H10: cutoff38 - Janneke | I10: 0.12557561 | J10: =0.53/(0.53+0.29) -> 0.64634146 | K10: softwood share in beam | L10: 450 kg/m3, 0.53 share | M10: =1/450 -> 0.0022222222
B11: sawnwood, beam, hardwood, dried (u=20%), planed | planing, beam, hardwood, u=20% | Europe without Switzerland | cubic meter | cutoff38 - Janneke | C11: 0.0012804097 | D11: cubic meter | E11: sawnwood, beam, hardwood, dried (u=20%), planed | F11: planing, beam, hardwood, u=20% | G11: Europe without Switzerland | H11: cutoff38 - Janneke | I11: 0.065173906 | J11: =0.29/(0.53+0.29) -> 0.35365854 | K11: hardwood share in beam | L11: 650 kg/m3, 0.29 share | M11: =1/650 -> 0.0015384615
B12: sawnwood, board, hardwood, dried (u=20%), planed | planing, board, hardwood, u=20% | Europe without Switzerland | cubic meter | cutoff38 - Janneke | C12: 0.0012804097 | D12: cubic meter | E12: sawnwood, board, hardwood, dried (u=20%), planed | F12: planing, board, hardwood, u=20% | G12: Europe without Switzerland | H12: cutoff38 - Janneke | I12: 0.083101444 | L12: 650 kg/m3, 0.18 share
B13: cross-laminated timber | cross-laminated timber production | RER | cubic meter | cutoff38 - Janneke | C13: 1 | D13: cubic meter | E13: cross-laminated timber | F13: cross-laminated timber production | G13: RER | H13: cutoff38 - Janneke | I13: 0.29640801 | J13: 0.4663 | K13: Share in scenario Biobased only. Other are multiplied by 0.5337 | L13: 490 kg/m3 | M13: =1/490 -> 0.0020408163
A14: Insulation | B14: stone wool | stone wool production | RoW | kilogram | cutoff38 - Janneke | C14: 1 | D14: kilogram | E14: stone wool | F14: stone wool production | G14: RoW | H14: cutoff38 - Janneke | I14: 1.3052964 | J14: 0.22
B15: glass wool mat | glass wool mat production | RoW | kilogram | cutoff38 - Janneke | C15: 1 | D15: kilogram | E15: glass wool mat | F15: glass wool mat production | G15: RoW | H15: cutoff38 - Janneke | I15: 2.672248 | J15: 0.37
B16: polyurethane, flexible foam | polyurethane production, flexible foam, MDI-based | RER | kilogram | cutoff38 - Janneke | C16: 1 | D16: kilogram | E16: polyurethane, flexible foam | F16: polyurethane production, flexible foam, MDI-based | G16: RER | H16: cutoff38 - Janneke | I16: 4.6140345 | J16: 0.08 | K16: replaced with flax wool in biobased, replaced with stonewool in circular
B17: polystyrene, extruded | polystyrene production, extruded, CO2 blown | RoW | kilogram | cutoff38 - Janneke | C17: 1 | D17: kilogram | E17: polystyrene, extruded | F17: polystyrene production, extruded, CO2 blown | G17: RoW | H17: cutoff38 - Janneke | I17: 4.2734114 | J17: 0.06 | K17: replaced with wood fibre softboard in biobased and circular
B18: polystyrene, expandable | polystyrene production, expandable | RER | kilogram | cutoff38 - Janneke | C18: 1 | D18: kilogram | E18: polystyrene, expandable | F18: polystyrene production, expandable | G18: RER | H18: cutoff38 - Janneke | I18: 3.5415258 | J18: 0.27 | K18: replaced with wood fibre softboard in biobased and circular
B19: residual wood, dry | fibreboard production, soft, from wet & dry processes | Europe without Switzerland | cubic meter | cutoff38 - Janneke | C19: 1 | D19: kg | E19: residual wood, dry | F19: fibreboard production, soft, from wet & dry processes | G19: Europe without Switzerland | H19: cutoff38 - Janneke | I19: =26.9621632999221/300 -> 0.089873878 | K19: 300 kg/m3. equal impacts assumed for flax wool insulation | L19: =1/300 -> 0.0033333333
A20: stone, sand-lime stone | B20: sand-lime brick | sand-lime brick production | DE | kilogram | cutoff38 - Janneke | C20: 1 | D20: kilogram | E20: sand-lime brick | F20: sand-lime brick production | G20: DE | H20: cutoff38 - Janneke | I20: 0.14945709
A21: Ceramic tile | B21: ceramic tile | ceramic tile production | RoW | kilogram | cutoff38 - Janneke | C21: 1 | D21: kilogram | E21: ceramic tile | F21: ceramic tile production | G21: RoW | H21: cutoff38 - Janneke | I21: 0.72968192
A22: Copper | B22: copper, cathode | copper production, cathode, solvent extraction and electrowinning process | GLO | kilogram | cutoff38 - Janneke | C22: 1 | D22: kilogram | E22: copper, cathode | F22: copper production, cathode, solvent extraction and electrowinning process | G22: GLO | H22: cutoff38 - Janneke | I22: 6.7357284
A23: Paint & glue | B23: alkyd paint, white, without solvent, in 60% solution state | alkyd paint production, white, solvent-based, product in 60% solution state | RoW | kilogram | cutoff38 - Janneke | C23: 1 | D23: kilogram | E23: alkyd paint, white, without solvent, in 60% solution state | F23: alkyd paint production, white, solvent-based, product in 60% solution state | G23: RoW | H23: cutoff38 - Janneke | I23: 6.6237906
A24: Steel & iron, other metals | B24: steel, low-alloyed | steel production, converter, low-alloyed | RER | kilogram | cutoff38 - Janneke | C24: 1 | D24: kilogram | E24: steel, low-alloyed | F24: steel production, converter, low-alloyed | G24: RER | H24: cutoff38 - Janneke | I24: 2.1587681
A25: Paper | B25: paper, woodfree, coated | paper production, woodfree, coated, at integrated mill | RER | kilogram | cutoff38 - Janneke | C25: 1 | D25: kilogram | E25: paper, woodfree, coated | F25: paper production, woodfree, coated, at integrated mill | G25: RER | H25: cutoff38 - Janneke | I25: 1.0502989
A26: Sand | B26: sand | gravel and sand quarry operation | RoW | kilogram | cutoff38 - Janneke | C26: 1 | D26: kilogram | E26: sand | F26: gravel and sand quarry operation | G26: RoW | H26: cutoff38 - Janneke | I26: 0.0041984599
A27: Plastics | B27: polyvinylchloride, suspension polymerised | polyvinylchloride production, suspension polymerisation | RER | kilogram | cutoff38 - Janneke | C27: 1 | D27: kilogram | E27: polyvinylchloride, suspension polymerised | F27: polyvinylchloride production, suspension polymerisation | G27: RER | H27: cutoff38 - Janneke | I27: 1.897504
A29: References
A30: Wernet, G., Bauer, C., Steubing, B., Reinhard, J., Moreno-Ruiz, E., & Weidema, B. (2016). The ecoinvent database version 3 (part I): Overview and methodology. The International Journal of Life Cycle Assessment, 21(9), 1218–1230. https://doi.org/10.1007/s11367-016-1087-8

Sheet GHG_Secondary_production
B1: index | C1: amount | D1: unit | E1: reference product | F1: name | G1: location | H1: database | I1: IPCC 2013 | climate change | GWP 100a | J1: Share | K1: Assumptions | L1: LCA value recycled content
A2: Aluminum | B2: aluminium, wrought alloy | treatment of aluminium scrap, post-consumer, prepared for recycling, at remelter | RER | kilogram | cutoff38 - Janneke | C2: 1 | D2: kilogram | E2: aluminium, wrought alloy | F2: treatment of aluminium scrap, post-consumer, prepared for recycling, at remelter | G2: RER | H2: cutoff38 - Janneke | I2: 0.77382136 | J2: 0.61 | K2: involves building demolition, collection, sorting, melting and casting; output is aluminium, wrought alloy, assuming 39% is refined and 61% is remelted, based on Zhong et al. (2021) | L2: 1
B3: aluminium, cast alloy | treatment of aluminium scrap, post-consumer, prepared for recycling, at refiner | RER | kilogram | cutoff38 - Janneke | C3: 1 | D3: kilogram | E3: aluminium, cast alloy | F3: treatment of aluminium scrap, post-consumer, prepared for recycling, at refiner | G3: RER | H3: cutoff38 - Janneke | I3: 0.86749393 | J3: 0.39 | L3: 1
A4: Clay brick, sand-lime stone, ceramic tile, stone | B4: clay brick | clay brick production, recycling JvO | RER | kilogram | cutoff38 - Janneke | C4: 1 | D4: kilogram | E4: clay brick | F4: clay brick production, recycling JvO | G4: RER | H4: cutoff38 - Janneke | I4: 0.22468702 | K4: Recycled content is max 25% (KNB, n.d.), included in calculation in separate step | L4: 1
B5: waste brick | treatment of waste brick, sorting plant | Europe without Switzerland | kilogram | cutoff38 - Janneke | C5: 1 | D5: kilogram | E5: waste brick | F5: treatment of waste brick, sorting plant | G5: Europe without Switzerland | H5: cutoff38 - Janneke | I5: 0.0082310004 | K5: "Energy for dismantling, particulate matter emissions from dismantling and handling, machines for handling in sorting plant, electricity demand for sorting plant, transport to dismantling facilities, final disposal of waste material." (Wernet et al., 2016) | L5: 1
A6: Concrete | B6: concrete, 30MPa | concrete production 30MPa, secondary coarse aggregate (37% RC) | RoW | cubic meter | cutoff38 - Janneke | C6: 0.000431779 | D6: cubic meter | E6: concrete, 30MPa | F6: concrete production 30MPa, secondary coarse aggregate (37% RC) | G6: RoW | H6: cutoff38 - Janneke | I6: 0.12620658 | K6: Density is 2316 kg/m3, 37% is gravel, which is replaced by secondary coarse aggregate, based on the Wet processing process as described by Zhang et al. (2021). | L6: 0.37
A7: Bitumen | B7: bitumen seal | bitumen seal production, recycling JvO | RER | kilogram | cutoff38 - Janneke | C7: 1 | D7: kilogram | E7: bitumen seal | F7: bitumen seal production, recycling JvO | G7: RER | H7: cutoff38 - Janneke | I7: 0.12161696 | K7: input materials are removed, including paper, quicklime, fleece, pitch, silica sand, polystyrene, etc. | L7: 1
B8: waste concrete, not reinforced | treatment of waste concrete, not reinforced, sorting plant | Europe without Switzerland | kilogram | cutoff38 - Janneke | C8: 1 | D8: kilogram | E8: waste concrete, not reinforced | F8: treatment of waste concrete, not reinforced, sorting plant | G8: Europe without Switzerland | H8: cutoff38 - Janneke | I8: 0.008849179 | K8: demolition like concrete | L8: 1
A9: Electronics | B9: copper, cathode | treatment of metal part of electronics scrap, in copper, anode, by electrolytic refining | RoW | kilogram | cutoff38 - Janneke | C9: 1 | D9: kilogram | E9: copper, cathode | F9: treatment of metal part of electronics scrap, in copper, anode, by electrolytic refining | G9: RoW | H9: cutoff38 - Janneke | I9: 0.30538773 | J9: 0.5 | L9: 1
B10: polyvinylchloride, suspension polymerised | polyvinylchloride production, suspension polymerisation, recycling JvO | RER | kilogram | cutoff38 - Janneke | C10: 1 | D10: kilogram | E10: polyvinylchloride, suspension polymerised | F10: polyvinylchloride production, suspension polymerisation, recycling JvO | G10: RER | H10: cutoff38 - Janneke | I10: 1.1430134 | J10: 0.5 | K10: input of vinyl chlorde (0.999 kg) is removed, and replaced with plastic granulate production | L10: 1
A11: Gypsum | B11: waste gypsum plasterboard | treatment of waste gypsum plasterboard, sorting plant | CH | kilogram | cutoff38 - Janneke | C11: 1 | D11: kilogram | E11: waste gypsum plasterboard | F11: treatment of waste gypsum plasterboard, sorting plant | G11: CH | H11: cutoff38 - Janneke | I11: 0.011457397 | L11: 1
B12: gypsum fibreboard | gypsum fibreboard production, recycling JvO | RoW | kilogram | cutoff38 - Janneke | C12: 1 | D12: kilogram | E12: gypsum fibreboard | F12: gypsum fibreboard production, recycling JvO | G12: RoW | H12: cutoff38 - Janneke | I12: 0.18813415 | K12: input of stucco, water, waste paper, silicone, alkylbenzene sulfonate and patato starch is removed (total input was 1.18, 0.18 of water remains for production) | L12: 1
A13: Glass | B13: flat glass, uncoated | flat glass production, uncoated, recycling JvO | RER | kilogram | cutoff38 - Janneke | C13: 1 | D13: kilogram | E13: flat glass, uncoated | F13: flat glass production, uncoated, recycling JvO | G13: RER | H13: cutoff38 - Janneke | I13: 0.81945735 | J13: 0.07 | K13: input of silica sand, lime and stone ash (1.19 kg) is removed. Only 7% is recycled into new glass. Vlakglasrecycling Nederland (2020) | L13: 1
B14: waste glass sheet | treatment of waste glass sheet, sorting plant | Europe without Switzerland | kilogram | cutoff38 - Janneke | C14: 1 | D14: kilogram | E14: waste glass sheet | F14: treatment of waste glass sheet, sorting plant | G14: Europe without Switzerland | H14: cutoff38 - Janneke | I14: 0.0047833109 | J14: 0.07 | L14: 1
B15: glass wool mat, uncoated, Saint-Gobain ISOVER SA | glass wool mat production, with phenolic binder, uncoated, Saint-Gobain ISOVER SA | CH | kilogram | cutoff38 - Janneke | C15: 1 | D15: kilogram | E15: glass wool mat, uncoated, Saint-Gobain ISOVER SA | F15: glass wool mat production, with phenolic binder, uncoated, Saint-Gobain ISOVER SA | G15: CH | H15: cutoff38 - Janneke | I15: 0.60506759 | J15: 0.41 | K15: 41% of glass to glass wool: 77% recycled content | L15: 0.77
A16: Wood | B16: sawnwood, board, softwood, dried (u=20%), planed | planing, board, softwood, u=20%, JvO | Europe without Switzerland | cubic meter | cutoff38 - Janneke | C16: 0.003333 | D16: cubic meter | E16: sawnwood, board, softwood, dried (u=20%), planed | F16: planing, board, softwood, u=20%, JvO | G16: Europe without Switzerland | H16: cutoff38 - Janneke | I16: 0.0392282 | J16: 0.25 | K16: assuming that, similar like input, 82% of outflow is beam, of which 25% can be recycled into wooden boards. Input of wood is removed in original process | L16: 1
B17: particleboard, uncoated | particleboard production, uncoated, from secondary wood, JvO | RoW | cubic meter | cutoff38 - Janneke | C17: 0.00413 | D17: cubic meter | E17: particleboard, uncoated | F17: particleboard production, uncoated, from secondary wood, JvO | G17: RoW | H17: cutoff38 - Janneke | I17: 1.4261091 | J17: 0.08 | K17: assumining 18% of outflow is board, of which 80% can be recycled into particle board. In original process, inflow of wood is removed. | L17: 1
B18: waste gypsum plasterboard | treatment of waste gypsum plasterboard, sorting plant | CH | kilogram | cutoff38 - Janneke | C18: 1 | D18: kilogram | E18: waste gypsum plasterboard | F18: treatment of waste gypsum plasterboard, sorting plant | G18: CH | H18: cutoff38 - Janneke | I18: 0.011457397 | K18: Assuming building demolition, transportation & sorting like gypsum plasterboard | L18: 1
A19: Insulation | B19: Stonewool, 50% RC, JvO | Stone wool, 50% RC, JvO | GLO | kilogram | cutoff38 - Janneke | C19: 1 | D19: kilogram | E19: Stonewool, 50% RC, JvO | F19: Stone wool, 50% RC, JvO | G19: GLO | H19: cutoff38 - Janneke | I19: 0.67278638 | L19: 0.5
B20: Wood fibreboard, 80% RC, JvO | Wood fibreboard production, 80% RC, JvO | GLO | kilogram | cutoff38 - Janneke | C20: 1 | D20: kilogram | E20: Wood fibreboard, 80% RC, JvO | F20: Wood fibreboard production, 80% RC, JvO | G20: GLO | H20: cutoff38 - Janneke | I20: 0.039036843 | L20: 0.8
B21: Expanded Polystyrene, 12% RC, JvO | Expanded Polystyrene, 12% RC, JvO | GLO | kilogram | cutoff38 - Janneke | C21: 1 | D21: kilogram | E21: Expanded Polystyrene, 12% RC, JvO | F21: Expanded Polystyrene, 12% RC, JvO | G21: GLO | H21: cutoff38 - Janneke | I21: 3.2437948 | L21: 0.12
B22: Glass wool, 80% RC, JvO | Glass wool production, 80% RC, JvO | GLO | kilogram | cutoff38 - Janneke | C22: 1 | D22: kilogram | E22: Glass wool, 80% RC, JvO | F22: Glass wool production, 80% RC, JvO | G22: GLO | H22: cutoff38 - Janneke | I22: 0.57929596 | L22: 0.8
A23: Copper | B23: copper, cathode | treatment of metal part of electronics scrap, in copper, anode, by electrolytic refining | RoW | kilogram | cutoff38 - Janneke | C23: 1 | D23: kilogram | E23: copper, cathode | F23: treatment of metal part of electronics scrap, in copper, anode, by electrolytic refining | G23: RoW | H23: cutoff38 - Janneke | I23: 0.30538773 | L23: 1
A24: Steel & iron, Other metals | B24: steel, low-alloyed | steel production, electric, low-alloyed | Europe without Switzerland and Austria | kilogram | cutoff38 - Janneke | C24: 1 | D24: kilogram | E24: steel, low-alloyed | F24: steel production, electric, low-alloyed | G24: Europe without Switzerland and Austria | H24: cutoff38 - Janneke | I24: 0.5493453 | L24: 1
A25: Paper | B25: paper, woodfree, coated | paper production, woodfree, coated, at integrated mill, recycling JvO | RER | kilogram | cutoff38 - Janneke | C25: 1 | D25: kilogram | E25: paper, woodfree, coated | F25: paper production, woodfree, coated, at integrated mill, recycling JvO | G25: RER | H25: cutoff38 - Janneke | I25: 0.63209567 | K25: inputs are removed, including sulphate pulp, lime, kaolin, organic and inorganic chemicals, etc. | L25: 1
B26: waste gypsum plasterboard | treatment of waste gypsum plasterboard, sorting plant | CH | kilogram | cutoff38 - Janneke | C26: 1 | D26: kilogram | E26: waste gypsum plasterboard | F26: treatment of waste gypsum plasterboard, sorting plant | G26: CH | H26: cutoff38 - Janneke | I26: 0.011457397 | K26: Demolition and sorting like plasterboard | L26: 1
A27: Sand | B27: waste concrete gravel | treatment of waste concrete gravel, sorting plant | CH | kilogram | cutoff38 - Janneke | C27: 1 | D27: kilogram | E27: waste concrete gravel | F27: treatment of waste concrete gravel, sorting plant | G27: CH | H27: cutoff38 - Janneke | I27: 0.0059008884 | K27: Only sorting is required | L27: 1
A28: Plastic | B28: polyvinylchloride, suspension polymerised | polyvinylchloride production, suspension polymerisation, recycling JvO | RER | kilogram | cutoff38 - Janneke | C28: 1 | D28: kilogram | E28: polyvinylchloride, suspension polymerised | F28: polyvinylchloride production, suspension polymerisation, recycling JvO | G28: RER | H28: cutoff38 - Janneke | I28: 1.1430134 | L28: 1
A31: References
A32: KNB (n.d.). Hergebruik en Recycling. https://www.knb-keramiek.nl/themas/duurzaamheid/hergebruik-en-recycling/
A33: Vlakglas Recycling Nederland (2020). Jaarverslag 2020. https://www.vlakglasrecycling.nl/uploads/jaarverslagen/Jaarverslag%202020.pdf
A34: Wernet, G., Bauer, C., Steubing, B., Reinhard, J., Moreno-Ruiz, E., & Weidema, B. (2016). The ecoinvent database version 3 (part I): Overview and methodology. The International Journal of Life Cycle Assessment, 21(9), 1218–1230. https://doi.org/10.1007/s11367-016-1087-8
A35: Zhang, C. (2021). Chapter 2: Eco-efficiency assessment of technological innovations in high-grade concrete recycling.
A36: Zhong, X., Hu, M., Deetman, S., Steubing, B., Lin, H. X., Hernandez, G. A., Harpprecht, C., Zhang, C., Tukker, A., & Behrens, P. (2021). Global greenhouse gas emissions from residential and commercial building materials and mitigation strategies to 2060. Nature Communications, 12(1), 6126. https://doi.org/10.1038/s41467-021-26212-z

Sheet LCI_comparison
A1: WLO High + Urban | C1: Demand | D1: Concrete | E1: Clay brick | F1: Other construction materials | G1: Steel & iron | H1: Stone wool | I1: Glass wool | J1: EPS | K1: XPS | L1: PUR | M1: Wood fibre insulation | N1: Ceramics | O1: Glass | P1: Glass glasswool | Q1: Wood beam | R1: Wood board | S1: Other | T1: Plastics | U1: Aluminum | V1: Copper | W1: Other metals | X1: Other biobased materials
C2: Primary production | D2: =GHG_Primary_production!I4 -> 0.11748738 | E2: =GHG_Primary_production!I3 -> 0.24253743 | F2: =((GHG_Primary_production!I5+GHG_Primary_production!I8+GHG_Primary_production!I20+GHG_Primary_production!I26)/4) -> 0.37600124 | G2: =GHG_Primary_production!I24 -> 2.1587681 | H2: =GHG_Primary_production!I14 -> 1.3052964 | I2: =GHG_Primary_production!I15 -> 2.672248 | J2: =GHG_Primary_production!I18 -> 3.5415258 | K2: =GHG_Primary_production!I17 -> 4.2734114 | L2: =GHG_Primary_production!I16 -> 4.6140345 | M2: =GHG_Primary_production!I19 -> 0.089873878 | N2: =GHG_Primary_production!I21 -> 0.72968192 | O2: =GHG_Primary_production!I9 -> 0.96429253 | P2: 0 | Q2: =(GHG_Primary_production!I10*GHG_Primary_production!J10+GHG_Primary_production!I11*GHG_Primary_production!J11) -> 0.10421403 | R2: =GHG_Primary_production!I12 -> 0.083101444 | S2: =((GHG_Primary_production!I6*0.5+GHG_Primary_production!I7*0.5+GHG_Primary_production!I23+GHG_Primary_production!I25)/3) -> 3.9969019 | T2: =GHG_Primary_production!I27 -> 1.897504 | U2: =GHG_Primary_production!I2 -> 20.974113 | V2: =GHG_Primary_production!I22 -> 6.7357284 | W2: =GHG_Primary_production!I24 -> 2.1587681 | X2: =GHG_Primary_production!I12 -> 0.083101444
C3: Secondary production | D3: =GHG_Secondary_production!I6 -> 0.12620658 | E3: =(GHG_Secondary_production!I4+GHG_Secondary_production!I5) -> 0.23291802 | F3: =(((GHG_Secondary_production!I7+GHG_Secondary_production!I8)+(GHG_Secondary_production!I11+GHG_Secondary_production!I12)+(GHG_Secondary_production!I4+GHG_Secondary_production!I5))/3) -> 0.18765857 | G3: =GHG_Secondary_production!I24 -> 0.5493453 | H3: =GHG_Secondary_production!I19 -> 0.67278638 | I3: =GHG_Secondary_production!I22 -> 0.57929596 | J3: =GHG_Secondary_production!I21 -> 3.2437948 | M3: =GHG_Secondary_production!I20 -> 0.039036843 | N3: =(GHG_Secondary_production!I4+GHG_Secondary_production!I5) -> 0.23291802 | O3: =(GHG_Secondary_production!I13+GHG_Secondary_production!I14) -> 0.82424066 | P3: =GHG_Secondary_production!I15 -> 0.60506759 | Q3: =(GHG_Secondary_production!I16+GHG_Secondary_production!I18) -> 0.050685597 | R3: =(GHG_Secondary_production!I17+GHG_Secondary_production!I18) -> 1.4375665 | S3: =((GHG_Secondary_production!I26+GHG_Secondary_production!I25+(GHG_Secondary_production!I23+GHG_Secondary_production!I28)/2)/2) -> 0.68387681 | T3: =GHG_Secondary_production!I28 -> 1.1430134 | U3: =(GHG_Secondary_production!I2+GHG_Secondary_production!I3) -> 1.6413153 | V3: =GHG_Secondary_production!I23 -> 0.30538773 | W3: =GHG_Secondary_production!I24 -> 0.5493453 | X3: =Q3*0.5+R3*0.5 -> 0.74412603
A6: Corrected for MRC
A7: Secondary production | B7: MRC not included in value | D7: x | E7: 0.25 | F7: 0.37 | G7: 1 | H7: x | I7: x | J7: x | M7: x | N7: 0.25 | O7: 0.933 | P7: x | Q7: 1 | R7: 1 | T7: 0.5 | U7: 1 | V7: 1 | W7: 1 | X7: 1
B8: MRC included in value | D8: 0.37 | H8: 0.5 | I8: 0.8 | J8: 0.12 | M8: 0.8 | P8: 0.77
C9: Primary production | D9: =D2 -> 0.11748738 | E9: =E2 -> 0.24253743 | F9: =F2 -> 0.37600124 | G9: =G2 -> 2.1587681 | H9: =H2 -> 1.3052964 | I9: =I2 -> 2.672248 | J9: =J2 -> 3.5415258 | K9: =K2 -> 4.2734114 | ... X9: =X2 -> 0.083101444
C10: Secondary production | D10: =D3 -> 0.12620658 | E10: =E3*0.25+E2*0.75 -> 0.24013258 | F10: =F3*0.37+F2*0.63 -> 0.30631445 | G10: =G3 -> 0.5493453 | H10: =H3 -> 0.67278638 | I10: =I3 -> 0.57929596 | J10: =J3 -> 3.2437948 | K10: =K3 -> 0 | L10: =L3 -> 0 | M10: =M3 -> 0.039036843 | N10: =N3*0.25+N2*0.75 -> 0.60549094 | O10: =0.993*O3+(1-0.993)*O2 -> 0.82522103 | P10: =P3 -> 0.60506759 | Q10: =Q3 -> 0.050685597 | R10: =R3 -> 1.4375665 | S10: =S3 -> 0.68387681 | T10: =T2*0.5*T3*0.5 -> 0.54221812 | U10: =U3 -> 1.6413153 | V10: =V3 -> 0.30538773 | W10: =W3 -> 0.5493453 | X10: =X3 -> 0.74412603

Sheet RR_MRC
A1: Material | B1: EOL recycling rate (actual) | C1: EOL recycling rate (best practice) | D1: EOL recycling rate (100%) | E1: Maximum recycled content | F1: Sources | G1: Assumptions | O1: Wiprachtiger et al., 2020: EOL Recycling rate for various insulation materials, 2015, Switserland
A2: Concrete | B2: 0.285 | C2: =0.53*0.85 -> 0.4505 | D2: 1 | E2: 0.37 | F2: Betonakkoord (2018), Zhang (2021, chapter 2), Verhagen et al. (2021) | G2: In wet processing, 53% can be recycled as coarse aggregate. All gravel in primary concrete production is replaced with secondary coarse aggregate (37%) | O2: Use to deconstruction: | P2: Collection as single material | Q2: single material to recycling | R2: RR | S2: RR - total
A3: Brick | B3: 0.01 | C3: 0.95 | D3: 1 | E3: 0.25 | F3: KNB (n.d.), KNB (2022), Verhagen et al. (2021), BDA (2014) | N3: EPS | O3: 11642 | P3: 530 | Q3: 53 | R3: =Q3/O3 -> 0.0045524824 | S3: =SUM(Q3:Q8)/SUM(O3:O8) -> 0.014528632
A4: Other construction materials | B4: 0.285 | C4: =0.53*0.85 -> 0.4505 | D4: 1 | E4: 0.37 | F4: See Concrete | N4: Stone wool | O4: 42941 | P4: 15029 | Q4: 751 | R4: =Q4/O4 -> 0.017489113
A5: Steel & iron | B5: 0.9 | C5: 0.95 | D5: 1 | E5: 1 | F5: EuRIC (2018a), Bouwen met Staal (n.d.), Verhagen et al. (2021), Bowyer et al. (2015) | N5: XPS | O5: 7800 | P5: 355 | Q5: 0 | R5: =Q5/O5 -> 0
A6: PUR | B6: 0 | C6: 0 | D6: 1 | E6: 0 | F6: Wiprachtiger et al. (2020) | N6: PUR | O6: 3185 | P6: 145 | Q6: 0 | R6: =Q6/O6 -> 0
A7: XPS | B7: 0 | C7: 0 | D7: 1 | E7: 0 | F7: Wiprachtiger et al. (2020) | N7: Glass wool | O7: 20071 | P7: 7025 | Q7: 476 | R7: =Q7/O7 -> 0.023715809
A8: EPS | B8: 0.005 | C8: =0.75*0.9 -> 0.675 | D8: 1 | E8: 0.12 | F8: Wiprachtiger et al. (2020), EPS Industry Alliance (2016) | N8: wood fiber | O8: 3633 | P8: 165 | Q8: 17 | R8: =Q8/O8 -> 0.0046793284
A9: Glass wool | B9: 0.024 | C9: =0.75*0.9 -> 0.675 | D9: 1 | E9: 0.8 | F9: Wiprachtiger et al. (2020), Isover (2018)
A10: Rock wool | B10: 0.017 | C10: =0.75*0.9 -> 0.675 | D10: 1 | E10: 0.5 | F10: Wiprachtiger et al. (2020), Bouwfisica (2018) & Rockwool (n.d.)
A11: Wood insulation | B11: 0.005 | C11: =0.75*0.9 -> 0.675 | D11: 1 | E11: 0.8 | F11: Wiprachtiger et al. (2020) | G11: Maximum recycled content as glass wool
A12: Ceramics | B12: 0.01 | C12: 0.95 | D12: 1 | E12: 0.25 | F12: See Brick
A13: Glass to glass | B13: =0.073*0.95 -> 0.06935 | C13: 0.95 | D13: 1 | E13: 0.933 | F13: Vlakglas Recycling Nederland (2020) & Verhagen et al. (2021)
A14: Glass to glass wool | B14: =0.43*0.95 -> 0.4085 | C14: 0.95 | D14: 0 | E14: 0.77 | F14: Vlakglas Recycling Nederland (2020), ISOVER St. Gobain (2018) & Verhagen et al. (2021)
A15: Wooden beam to board* | B15: =0.25*0.95 -> 0.2375 | C15: 0.95 | D15: 1 | E15: 1 | F15: Mehr et al. (2018) & Verhagen et al. (2021) | G15: Beam is sawn into smaller pieces: boards
A16: Wooden board to particle board* | B16: =0.8*0.95 -> 0.76 | C16: 0.95 | D16: 1 | E16: 1 | F16: Mehr et al. (2018) & Verhagen et al. (2021) | G16: particle board consists of secondary wood and chemicals
A17: Other | B17: p.m. | C17: p.m. | D17: p.m. | E17: p.m. | F17: Metabolic (2021) | G17: Maximum recycled content based upon plastics and copper (electronics)
A18: Plastics | B18: 0.25 | C18: 0.9 | D18: 1 | E18: 0.5 | F18: EuRIC (2018b) & ASBP (2021), Verhagen et al. (2021) | G18: Theoretical EOL RR based upon mean of Verhagen et al. (2020)
A19: Aluminum | B19: 0.9 | C19: 0.95 | D19: 1 | E19: 1 | F19: EuRIC (2018a)
A20: Copper | B20: 0.8 | C20: 0.95 | D20: 1 | E20: 1 | F20: EuRIC (2018a)
A21: Other metals | B21: 0.9 | C21: 0.95 | D21: 1 | E21: 1 | F21: See steel & iron
A22: Other biobased materials | B22: =(B15+B16)/2 -> 0.49875 | C22: 0.95 | D22: 1 | E22: 1 | F22: See wood
A25: * 82% is beam, 18% is board, 25% of beam can be recycled into boards, 80% of board can be recycled into particleboard (Mehr et al., 2018)
A26: * beam, board ratio is based on : Heeren et al. (2015)
A29: References:
A30: ASBP (2021). Recycled plastics in construction – Is it a good thing? https://asbp.org.uk/asbp-news/think-piece-recycled-plastics
A31: BDA (2014). BDA comment on the use of Reclaimed Clay Bricks. https://www.brick.org.uk/admin/resources/g-reclaimed-brickwork.pdf
A32: Betonakkoord (2018). Betonakkoord voor duurzame groei. https://www.betonakkoord.nl/
