Workbook

Sheet Building_MI
B1: Unit | C1: kg/m2 UFA | D1: kg/m2 UFA | E1: kg/m2 UFA | F1: kg/m2 UFA | G1: kg/m2 UFA | H1: kg/m2 UFA | I1: kg/m2 UFA | J1: kg/m2 UFA | K1: kg/m2 UFA | L1: kg/m2 UFA | M1: kg/m2 UFA | N1: kg/m2 UFA | O1: kg/m2 UFA | P1: kg/m2 UFA | Q1: kg/m2 UFA | R1: kg/m2 UFA | S1: kg/m2 UFA | T1: kg/m2 UFA | U1: kg/m2 UFA | V1: kg/m2 UFA | W1: kg/m2 UFA | X1: kg/m2 UFA | Y1: kg/m2 UFA | Z1: kg/m2 UFA | AA1: kg/m2 UFA
B2: BONSAI Waste Treatment | C2: M_wAlum | D2: M_wCons | E2: M_wCons | F2: M_wCons | G2: M_wDisc_eq | H2: M_wCons | I2: M_wGlas | J2: M_wWood | K2: M_wCons | L2: M_wCons | M2: M_wCons | N2: M_wCons | O2: M_wCons | P2: M_wCons | Q2: M_wCons | R2: M_wCopp | S2: M_wPlas | T2: M_wCons | U2: M_wCons | V2: M_wWood | W2: M_wMix_nonferr | X2: M_wPape | Y2: M_wStel | Z2: M_wCons | AA2: M_wCons
B3: BONSAI_2nd | F3: M_CMNT | Q3: M_CRMC | S3: M_PLAS | W3: M_ONFM | Y3: M_STEL
B4: BONSAI | C4: M_ALUM | D4: M_BRIK | E4: M_CMNT + M_SDCL | F4: M_BITU | G4: M_ELMA | H4: M_BRIK | I4: M_GLAS | J4: M_WOOD | K4: M_GLAS | L4: M_RUBP | M4: M_ONMM | N4: M_RUBP | O4: M_RUBP | P4: M_BRIK | Q4: M_BRIK | R4: M_COPP | S4: M_RUBP | T4: M_CHEM | U4: M_BRIK | V4: M_WOOD | W4: M_LZTP | X4: M_PAPE | Y4: M_FABM | Z4: M_STON | AA4: M_SDCL
A5: Building type | B5: Building age | C5: Aluminium (kg/m2) | D5: Baksteen (kg/m2) | E5: Beton (kg/m2) | F5: Bitumen (kg/m2) | G5: Electronica (kg/m2) | H5: Gips (kg/m2) | I5: Glas (kg/m2) | J5: Hout (kg/m2) | K5: Glass wool | L5: Expanded polystyrene | M5: Stone wool | N5: Polyurethanes | O5: Extruded polystyrene | P5: Kalkzandsteen (kg/m2) | Q5: Keramiek (kg/m2) | R5: Koper (kg/m2) | S5: Kunststoffen (kg/m2) | T5: Lijm en verf (kg/m2) | U5: Mortel | V5: Overig biobased | W5: Overige metalen (kg/m2) | X5: Papier (kg/m2) | Y5: Staal & IJzer (kg/m2) | Z5: Steen (kg/m2) | AA5: Zand (kg/m2)
A6: detached (vrijstaand) | B6: pre 1945 | C6: 0.11230813 | D6: 290.13366 | E6: 1376.7649 | F6: 0 | G6: 0.014084507 | H6: 9.3222155 | I6: 0 | J6: 181.00587 | K6: =$AG6*AI$35 -> 0 | L6: =$AG6*AJ$35 -> 0 | M6: =$AG6*AK$35 -> 0 | N6: =$AG6*AL$35 -> 0 | O6: =$AG6*AM$35 -> 0 | P6: 307.73568 | Q6: 33.736131 | R6: 0.91964414 | S6: 1.3289144 | T6: 1.5227198 | W6: 3.9420607 | X6: 0 | Y6: 69.751482 | Z6: 22.052395 | AA6: 25.486251
B7: 1945-1970 | C7: {=(25/30)*Building_MI_original_baseline!C7:AA7+(5/30)*Building_MI_original_baseline!C8:AA8} -> 0.20493011 | D7: 261.12029 | E7: 1365.0112 | F7: 0.038644566 | G7: 0.014084507 | H7: 31.410363 | I7: 3.7677497 | J7: 86.203569 | K7: 5.230049 | L7: 3.8165223 | M7: 3.1097589 | N7: 1.1308214 | O7: 0.84811606 | P7: 365.67702 | Q7: 28.504743 | R7: 0.91964414 | S7: 1.6124202 | T7: 1.5013964 | U7: 0 | V7: 0 | W7: 3.9451693 | X7: 0.2419383 | Y7: 54.621778 | Z7: 22.240804 | AA7: 25.486251
B8: 1970-2000 | C8: {=(25/30)*Building_MI_original_baseline!C8:AA8+(5/30)*Building_MI_original_baseline!C9:AA9} -> 0.19397869 | D8: 116.05346 | E8: 1310.8141 | F8: 0.23186739 | G8: 0.014084507 | H8: 31.410363 | I8: 6.4589995 | J8: 26.884629 | K8: 5.5319407 | L8: 4.0368216 | M8: 3.289262 | N8: 1.1960953 | O8: 0.89707146 | P8: 655.38373 | Q8: 2.3478011 | R8: 0.91964414 | S8: 1.7965502 | T8: 1.4857841 | U8: 0 | V8: 0 | W8: 3.9451693 | X8: 0.2419383 | Y8: 44.197687 | Z8: 23.182847 | AA8: 25.486251
B9: 2000-2018 | C9: 0.19397869 | D9: 116.05346 | E9: 1310.8141 | F9: 0.23186739 | G9: 0.014084507 | H9: 31.410363 | I9: 6.4589995 | J9: 35.69002 | K9: =$AG9*AI$35 -> 0 | L9: =$AG9*AJ$35 -> 0 | M9: =$AG9*AK$35 -> 0 | N9: =$AG9*AL$35 -> 0 | O9: =$AG9*AM$35 -> 0 | P9: 655.38373 | Q9: 2.3478011 | R9: 0.91964414 | S9: 1.7965502 | T9: 1.5506931 | W9: 3.9451693 | X9: 0.2419383 | Y9: 44.186521 | Z9: 23.182847 | AA9: 25.486251
B10: 2018-2050 | C10: 1.8059701 | D10: 218.41791 | E10: 1190.3881 | F10: 0.10447761 | G10: 0.62686567 | H10: 15.820896 | I10: 11.134328 | J10: 34.328358 | K10: =$AG10*AI$35 -> 0 | L10: =$AG10*AJ$35 -> 0 | M10: =$AG10*AK$35 -> 0 | N10: =$AG10*AL$35 -> 0 | O10: =$AG10*AM$35 -> 0 | P10: 0 | Q10: 5.358209 | R10: 0.47761194 | S10: 2.4029851 | T10: 0.92537313 | U10: 82.910448 | V10: 0 | W10: 0.11940299 | X10: 1.3731343 | Y10: 25.686567 | Z10: 0.044776119 | AA10: 99.507463
A11: semi-detached (2-1 kap) / corner (hoek) | B11: pre 1945 | C11: 0.18886813 | D11: 322.16942 | E11: 1388.6241 | F11: 0 | G11: 0.0070422535 | H11: 10.021588 | I11: 0.18055071 | J11: 88.178593 | K11: =$AG11*AI$35 -> 0 | L11: =$AG11*AJ$35 -> 0 | M11: =$AG11*AK$35 -> 0 | N11: =$AG11*AL$35 -> 0 | O11: =$AG11*AM$35 -> 0 | P11: 327.72171 | Q11: 3.3205046 | R11: 0.84813829 | S11: 1.2349096 | T11: 1.6288592 | W11: 1.3351706 | X11: 0 | Y11: 59.321163 | Z11: 0.47078742 | AA11: 20.141575
B12: 1945-1970 | C12: {=(25/30)*Building_MI_original_baseline!C12:AA12+(5/30)*Building_MI_original_baseline!C13:AA13} -> 0.28178136 | D12: 289.95247 | E12: 1521.8743 | F12: 0 | G12: 0.0070422535 | H12: 46.677547 | I12: 2.8769816 | J12: 48.55471 | K12: 5.539676 | L12: 4.0424663 | M12: 3.2938614 | N12: 1.1977678 | O12: 0.89832584 | P12: 394.5218 | Q12: 3.3205046 | R12: 0.84813829 | S12: 1.5919649 | T12: 1.7222954 | U12: 0 | V12: 0 | W12: 1.3770229 | X12: 0.36854849 | Y12: 61.77004 | Z12: 0.60906715 | AA12: 20.141575
B13: 1970-2000 | C13: {=(25/30)*Building_MI_original_baseline!C13:AA13+(5/30)*Building_MI_original_baseline!C14:AA14} -> 0.25258703 | D13: 128.86777 | E13: 1589.9202 | F13: 0 | G13: 0.0070422535 | H13: 46.677547 | I13: 4.8030037 | J13: 30.892645 | K13: 5.7969504 | L13: 4.2302071 | M13: 3.4468354 | N13: 1.2533947 | O13: 0.94004601 | P13: 728.52222 | Q13: 3.3205046 | R13: 0.84813829 | S13: 1.8044713 | T13: 1.751331 | U13: 0 | V13: 0 | W13: 1.3770229 | X13: 0.36854849 | Y13: 63.322801 | Z13: 1.3004658 | AA13: 20.141575
B14: 2000-2018 | C14: 0.25258703 | D14: 128.86777 | E14: 1589.9202 | F14: 0 | G14: 0.0070422535 | H14: 46.677547 | I14: 4.8030037 | J14: 42.414407 | K14: =$AG14*AI$35 -> 0 | L14: =$AG14*AJ$35 -> 0 | M14: =$AG14*AK$35 -> 0 | N14: =$AG14*AL$35 -> 0 | O14: =$AG14*AM$35 -> 0 | P14: 728.52222 | Q14: 3.3205046 | R14: 0.84813829 | S14: 1.8044713 | T14: 1.8392071 | W14: 1.3770229 | X14: 0.36854849 | Y14: 63.308935 | Z14: 1.3004658 | AA14: 20.141575
B15: 2018-2050 | C15: 1.8059701 | D15: 218.41791 | E15: 1190.3881 | F15: 0.10447761 | G15: 0.62686567 | H15: 15.820896 | I15: 11.134328 | J15: 34.328358 | K15: =$AG15*AI$35 -> 0 | L15: =$AG15*AJ$35 -> 0 | M15: =$AG15*AK$35 -> 0 | N15: =$AG15*AL$35 -> 0 | O15: =$AG15*AM$35 -> 0 | P15: 0 | Q15: 5.358209 | R15: 0.47761194 | S15: 2.4029851 | T15: 0.92537313 | U15: 82.910448 | V15: 0 | W15: 0.11940299 | X15: 1.3731343 | Y15: 25.686567 | Z15: 0.044776119 | AA15: 99.507463
A16: row house (tussenwoning) | B16: pre 1945 | C16: 0.37854946 | D16: 162.86606 | E16: 1144.3173 | F16: 0 | G16: 0.018924161 | H16: 7.6938449 | I16: 0.23043419 | J16: 64.768413 | K16: =$AG16*AI$35 -> 0 | L16: =$AG16*AJ$35 -> 0 | M16: =$AG16*AK$35 -> 0 | N16: =$AG16*AL$35 -> 0 | O16: =$AG16*AM$35 -> 0 | P16: 263.36175 | Q16: 2.7625527 | R16: 0.3514936 | S16: 0.81826994 | T16: 1.3552015 | W16: 1.469714 | X16: 0 | Y16: 51.236411 | Z16: 0.43873776 | AA16: 25.673779
B17: 1945-1970 | C17: {=(25/30)*Building_MI_original_baseline!C17:AA17+(5/30)*Building_MI_original_baseline!C18:AA18} -> 0.45919951 | D17: 146.57946 | E17: 1238.7901 | F17: 0 | G17: 0.018924161 | H17: 16.722917 | I17: 2.6610481 | J17: 37.434904 | K17: 5.009172 | L17: 3.6553417 | M17: 2.9784266 | N17: 1.0830642 | O17: 0.81229816 | P17: 290.68927 | Q17: 2.7625527 | R17: 0.3514936 | S17: 1.2663895 | T17: 1.4637035 | U17: 0 | V17: 0 | W17: 1.5202925 | X17: 0.47785589 | Y17: 53.458639 | Z17: 0.56953657 | AA17: 25.673779
B18: 1970-2000 | C18: {=(25/30)*Building_MI_original_baseline!C18:AA18+(5/30)*Building_MI_original_baseline!C19:AA19} -> 0.37808582 | D18: 65.146426 | E18: 1304.4812 | F18: 0 | G18: 0.018924161 | H18: 16.722917 | I18: 4.3972009 | J18: 22.392487 | K18: 5.1915102 | L18: 3.7883993 | M18: 3.0868439 | N18: 1.1224887 | O18: 0.84186652 | P18: 427.32687 | Q18: 2.7625527 | R18: 0.3514936 | S18: 1.871411 | T18: 1.4762391 | U18: 0 | V18: 0 | W18: 1.5202925 | X18: 0.47785589 | Y18: 54.822602 | Z18: 1.2235306 | AA18: 25.673779
B19: 2000-2018 | C19: 0.37808582 | D19: 65.146426 | E19: 1304.4812 | F19: 0 | G19: 0.018924161 | H19: 16.722917 | I19: 4.3972009 | J19: 32.834915 | K19: =$AG19*AI$35 -> 0 | L19: =$AG19*AJ$35 -> 0 | M19: =$AG19*AK$35 -> 0 | N19: =$AG19*AL$35 -> 0 | O19: =$AG19*AM$35 -> 0 | P19: 427.32687 | Q19: 2.7625527 | R19: 0.3514936 | S19: 1.871411 | T19: 1.556601 | W19: 1.5202925 | X19: 0.47785589 | Y19: 54.810217 | Z19: 1.2235306 | AA19: 25.673779
B20: 2018-2050 | C20: 1.1980676 | D20: 179.96618 | E20: 1662.6232 | F20: 0.64251208 | G20: 0.89855072 | H20: 13.541063 | I20: 7.5458937 | J20: 24.903382 | K20: =$AG20*AI$35 -> 0 | L20: =$AG20*AJ$35 -> 0 | M20: =$AG20*AK$35 -> 0 | N20: =$AG20*AL$35 -> 0 | O20: =$AG20*AM$35 -> 0 | P20: 0 | Q20: 6.5748792 | R20: 0.58454106 | S20: 2.8743961 | T20: 0.78743961 | U20: 63.603865 | V20: 0 | W20: 0.12077295 | X20: 0.58454106 | Y20: 29.855072 | Z20: 0.096618357 | AA20: 128.72947
A21: multiple fam (meergezins) | B21: pre 1945 | C21: 0.2022183 | D21: 169.9378 | E21: 1421.6139 | F21: 0 | G21: 0.032032279 | H21: 13.986689 | I21: 0.23152289 | J21: 33.943423 | K21: =$AG21*AI$35 -> 0 | L21: =$AG21*AJ$35 -> 0 | M21: =$AG21*AK$35 -> 0 | N21: =$AG21*AL$35 -> 0 | O21: =$AG21*AM$35 -> 0 | P21: 224.76978 | Q21: 12.270727 | R21: 0.30749103 | S21: 0.99483574 | T21: 2.0525548 | W21: 0.72710812 | X21: 0 | Y21: 69.102116 | Z21: 0.83496119 | AA21: 16.468138
B22: 1945-1970 | C22: {=(25/30)*Building_MI_original_baseline!C22:AA22+(5/30)*Building_MI_original_baseline!C23:AA23} -> 0.30659409 | D22: 150.7074 | E22: 1514.6211 | F22: 0.1376447 | G22: 0.032032279 | H22: 13.822344 | I22: 2.9457613 | J22: 21.144124 | K22: 6.7453931 | L22: 4.9223139 | M22: 4.0107743 | N22: 1.4584634 | O22: 1.0938475 | P22: 241.44039 | Q22: 11.175228 | R22: 0.30764778 | S22: 1.338394 | T22: 5.6162251 | U22: 0 | V22: 0 | W22: 0.74128453 | X22: 0.35798067 | Y22: 68.932509 | Z22: 0.73466772 | AA22: 16.468138
B23: 1970-2000 | C23: {=(25/30)*Building_MI_original_baseline!C23:AA23+(5/30)*Building_MI_original_baseline!C24:AA24} -> 0.78220972 | D23: 54.555367 | E23: 1526.4957 | F23: 0.8258682 | G23: 0.032032279 | H23: 13.00062 | I23: 4.8845031 | J23: 12.026846 | K23: 4.8355059 | L23: 3.5286124 | M23: 2.8751657 | N23: 1.0455148 | O23: 0.78413609 | P23: 324.79346 | Q23: 5.6977324 | R23: 0.3085099 | S23: 1.8858516 | T23: 5.605894 | U23: 0 | V23: 0 | W23: 0.74693622 | X23: 0.35798067 | Y23: 70.660171 | Z23: 0.88796921 | AA23: 16.468138
B24: 2000-2018 | C24: 0.78220972 | D24: 54.555367 | E24: 1526.4957 | F24: 0.8258682 | G24: 0.032032279 | H24: 13.00062 | I24: 4.8845031 | J24: 13.12516 | K24: =$AG24*AI$35 -> 0 | L24: =$AG24*AJ$35 -> 0 | M24: =$AG24*AK$35 -> 0 | N24: =$AG24*AL$35 -> 0 | O24: =$AG24*AM$35 -> 0 | P24: 324.79346 | Q24: 5.6977324 | R24: 0.30890178 | S24: 1.8877069 | T24: 5.5541377 | W24: 0.74699402 | X24: 0.35798067 | Y24: 70.647257 | Z24: 0.88796921 | AA24: 16.468138
B25: 2018-2050 | C25: 1.548913 | D25: 237.06522 | E25: 1107.9076 | F25: 0.31521739 | G25: 1.2880435 | H25: 30.875 | I25: 5.8913043 | J25: 2.2065217 | K25: =$AG25*AI$35 -> 0 | L25: =$AG25*AJ$35 -> 0 | M25: =$AG25*AK$35 -> 0 | N25: =$AG25*AL$35 -> 0 | O25: =$AG25*AM$35 -> 0 | P25: 0 | Q25: 12.581522 | R25: 0.375 | S25: 2.5054348 | T25: 0.99456522 | U25: 61.532609 | V25: 0 | W25: 0.125 | X25: 0.27173913 | Y25: 21.673913 | Z25: 0.5326087 | AA25: 30.11413

Sheet meta
A1: Meta Data | D1: file name
A2: Source | B2: Oorschot et al. 2023
A3: Empirical historic data | B3: MPG | C3: Metabolic data analyis | D3: historic_MI­_original
A4: Future model | B4: Metabolic | C4: Baseline in Oorschot analysis | D4: Metabolic_MI_scenarios_21102021

Sheet Building_MI_periodharmonised
C1: kg/m2 UFA | D1: kg/m2 UFA | E1: kg/m2 UFA | F1: kg/m2 UFA | G1: kg/m2 UFA | H1: kg/m2 UFA | I1: kg/m2 UFA | J1: kg/m2 UFA | K1: kg/m2 UFA | L1: kg/m2 UFA | M1: kg/m2 UFA | N1: kg/m2 UFA | O1: kg/m2 UFA | P1: kg/m2 UFA | Q1: kg/m2 UFA | R1: kg/m2 UFA | S1: kg/m2 UFA | T1: kg/m2 UFA | U1: kg/m2 UFA | V1: kg/m2 UFA | W1: kg/m2 UFA | X1: kg/m2 UFA | Y1: kg/m2 UFA | Z1: kg/m2 UFA | AA1: kg/m2 UFA | AG1: kg/m2 UFA
A2: Treatment | B2: BONSAI Waste | C2: M_wAlum | D2: M_wCons | E2: M_wCons | F2: M_wCons | G2: M_wDisc_eq | H2: M_wCons | I2: M_wGlas | J2: M_wWood | K2: M_wCons | L2: M_wCons | M2: M_wCons | N2: M_wCons | O2: M_wCons | P2: M_wCons | Q2: M_wCons | R2: M_wCopp | S2: M_wPlas | T2: M_wCons | U2: M_wCons | V2: M_wWood | W2: M_wMix_nonferr | X2: M_wPape | Y2: M_wStel | Z2: M_wCons | AA2: M_wCons
B3: BONSAI_2nd | F3: M_CMNT | Q3: M_CRMC | S3: M_PLAS | W3: M_ONFM | Y3: M_STEL
A4: Cradle-to-gate | B4: BONSAI | C4: M_ALUM | D4: M_BRIK | E4: M_CMNT + M_SDCL | F4: M_BITU | G4: M_ELMA | H4: M_BRIK | I4: M_GLAS | J4: M_WOOD | K4: M_GLAS | L4: M_RUBP | M4: M_ONMM | N4: M_RUBP | O4: M_RUBP | P4: M_BRIK | Q4: M_BRIK | R4: M_COPP | S4: M_RUBP | T4: M_CHEM | U4: M_BRIK | V4: M_WOOD | W4: M_LZTP | X4: M_PAPE | Y4: M_FABM | Z4: M_STON | AA4: M_SDCL
A5: Building type | B5: Building age | C5: Aluminium (kg/m2) | D5: Baksteen (kg/m2) | E5: Beton (kg/m2) | F5: Bitumen (kg/m2) | G5: Electronica (kg/m2) | H5: Gips (kg/m2) | I5: Glas (kg/m2) | J5: Hout (kg/m2) | K5: Glass wool | L5: Expanded polystyrene | M5: Stone wool | N5: Polyurethanes | O5: Extruded polystyrene | P5: Kalkzandsteen (kg/m2) | Q5: Keramiek (kg/m2) | R5: Koper (kg/m2) | S5: Kunststoffen (kg/m2) | T5: Lijm en verf (kg/m2) | U5: Mortel | V5: Overig biobased | W5: Overige metalen (kg/m2) | X5: Papier (kg/m2) | Y5: Staal & IJzer (kg/m2) | Z5: Steen (kg/m2) | AA5: Zand (kg/m2) | AB5: TOTAL | AG5: Isolatie (kg/m2)
A6: Detached | B6: 0-1945 | C6: 0.11230813 | D6: 290.13366 | E6: 1376.7649 | F6: 0 | G6: 0.014084507 | H6: 9.3222155 | I6: 0 | J6: 181.00587 | K6: =$AG6*AI$35 -> 5.0229685 | L6: =$AG6*AJ$35 -> 3.6654095 | M6: =$AG6*AK$35 -> 2.9866299 | N6: =$AG6*AL$35 -> 1.0860472 | O6: =$AG6*AM$35 -> 0.81453543 | P6: 307.73568 | Q6: 33.736131 | R6: 0.91964414 | S6: 1.3289144 | T6: 1.5227198 | W6: 3.9420607 | X6: 0 | Y6: 69.751482 | Z6: 22.052395 | AA6: 25.486251 | AB6: =SUM(C6:AA6) -> 2337.4039 | AG6: 13.575591
B7: 1946-1974 | C7: {=(25/30)*Building_MI_original_baseline!C7:AA7+(5/30)*Building_MI_original_baseline!C8:AA8} -> 0.20493011 | D7: 261.12029 | E7: 1365.0112 | F7: 0.038644566 | G7: 0.014084507 | H7: 31.410363 | I7: 3.7677497 | J7: 86.203569 | K7: 5.230049 | L7: 3.8165223 | M7: 3.1097589 | N7: 1.1308214 | O7: 0.84811606 | P7: 365.67702 | Q7: 28.504743 | R7: 0.91964414 | S7: 1.6124202 | T7: 1.5013964 | U7: 0 | V7: 0 | W7: 3.9451693 | X7: 0.2419383 | Y7: 54.621778 | Z7: 22.240804 | AA7: 25.486251 | AB7: =SUM(C7:AA7) -> 2266.6572 | AG7: 14.033811
B8: 1975-2005 | C8: {=(25/30)*Building_MI_original_baseline!C8:AA8+(5/30)*Building_MI_original_baseline!C9:AA9} -> 0.19397869 | D8: 116.05346 | E8: 1310.8141 | F8: 0.23186739 | G8: 0.014084507 | H8: 31.410363 | I8: 6.4589995 | J8: 26.884629 | K8: 5.5319407 | L8: 4.0368216 | M8: 3.289262 | N8: 1.1960953 | O8: 0.89707146 | P8: 655.38373 | Q8: 2.3478011 | R8: 0.91964414 | S8: 1.7965502 | T8: 1.4857841 | U8: 0 | V8: 0 | W8: 3.9451693 | X8: 0.2419383 | Y8: 44.197687 | Z8: 23.182847 | AA8: 25.486251 | AB8: =SUM(C8:AA8) -> 2266.0001 | AG8: 14.642552
B9: 2006-2022 | C9: 0.19397869 | D9: 116.05346 | E9: 1310.8141 | F9: 0.23186739 | G9: 0.014084507 | H9: 31.410363 | I9: 6.4589995 | J9: 35.69002 | K9: =$AG9*AI$35 -> 6.1029226 | L9: =$AG9*AJ$35 -> 4.4534841 | M9: =$AG9*AK$35 -> 3.6287648 | N9: =$AG9*AL$35 -> 1.3195508 | O9: =$AG9*AM$35 -> 0.98966312 | P9: 655.38373 | Q9: 2.3478011 | R9: 0.91964414 | S9: 1.7965502 | T9: 1.5506931 | W9: 3.9451693 | X9: 0.2419383 | Y9: 44.186521 | Z9: 23.182847 | AA9: 25.486251 | AB9: =SUM(C9:AA9) -> 2276.4024 | AG9: 16.494385
B10: 2018-2050 | C10: 1.8059701 | D10: 218.41791 | E10: 1190.3881 | F10: 0.10447761 | G10: 0.62686567 | H10: 15.820896 | I10: 11.134328 | J10: 34.328358 | K10: =$AG10*AI$35 -> 12.618657 | L10: =$AG10*AJ$35 -> 9.208209 | M10: =$AG10*AK$35 -> 7.5029851 | N10: =$AG10*AL$35 -> 2.7283582 | O10: =$AG10*AM$35 -> 2.0462687 | P10: 0 | Q10: 5.358209 | R10: 0.47761194 | S10: 2.4029851 | T10: 0.92537313 | U10: 82.910448 | V10: 0 | W10: 0.11940299 | X10: 1.3731343 | Y10: 25.686567 | Z10: 0.044776119 | AA10: 99.507463 | AB10: =SUM(C10:AA10) -> 1725.5373 | AG10: 34.104478
A11: Semi-Detached | B11: 0-1945 | C11: 0.18886813 | D11: 322.16942 | E11: 1388.6241 | F11: 0 | G11: 0.0070422535 | H11: 10.021588 | I11: 0.18055071 | J11: 88.178593 | K11: =$AG11*AI$35 -> 5.3200697 | L11: =$AG11*AJ$35 -> 3.882213 | M11: =$AG11*AK$35 -> 3.1632847 | N11: =$AG11*AL$35 -> 1.1502853 | O11: =$AG11*AM$35 -> 0.862714 | P11: 327.72171 | Q11: 3.3205046 | R11: 0.84813829 | S11: 1.2349096 | T11: 1.6288592 | W11: 1.3351706 | X11: 0 | Y11: 59.321163 | Z11: 0.47078742 | AA11: 20.141575 | AB11: =SUM(C11:AA11) -> 2239.7716 | AG11: 14.378567
B12: 1946-1974 | C12: {=(25/30)*Building_MI_original_baseline!C12:AA12+(5/30)*Building_MI_original_baseline!C13:AA13} -> 0.28178136 | D12: 289.95247 | E12: 1521.8743 | F12: 0 | G12: 0.0070422535 | H12: 46.677547 | I12: 2.8769816 | J12: 48.55471 | K12: 5.539676 | L12: 4.0424663 | M12: 3.2938614 | N12: 1.1977678 | O12: 0.89832584 | P12: 394.5218 | Q12: 3.3205046 | R12: 0.84813829 | S12: 1.5919649 | T12: 1.7222954 | U12: 0 | V12: 0 | W12: 1.3770229 | X12: 0.36854849 | Y12: 61.77004 | Z12: 0.60906715 | AA12: 20.141575 | AB12: =SUM(C12:AA12) -> 2411.4679 | AG12: 14.886733
B13: 1975-2005 | C13: {=(25/30)*Building_MI_original_baseline!C13:AA13+(5/30)*Building_MI_original_baseline!C14:AA14} -> 0.25258703 | D13: 128.86777 | E13: 1589.9202 | F13: 0 | G13: 0.0070422535 | H13: 46.677547 | I13: 4.8030037 | J13: 30.892645 | K13: 5.7969504 | L13: 4.2302071 | M13: 3.4468354 | N13: 1.2533947 | O13: 0.94004601 | P13: 728.52222 | Q13: 3.3205046 | R13: 0.84813829 | S13: 1.8044713 | T13: 1.751331 | U13: 0 | V13: 0 | W13: 1.3770229 | X13: 0.36854849 | Y13: 63.322801 | Z13: 1.3004658 | AA13: 20.141575 | AB13: =SUM(C13:AA13) -> 2639.8453 | AG13: 15.39892
B14: 2006-2022 | C14: 0.25258703 | D14: 128.86777 | E14: 1589.9202 | F14: 0 | G14: 0.0070422535 | H14: 46.677547 | I14: 4.8030037 | J14: 42.414407 | K14: =$AG14*AI$35 -> 6.2937005 | L14: =$AG14*AJ$35 -> 4.5927004 | M14: =$AG14*AK$35 -> 3.7422003 | N14: =$AG14*AL$35 -> 1.3608001 | O14: =$AG14*AM$35 -> 1.0206001 | P14: 728.52222 | Q14: 3.3205046 | R14: 0.84813829 | S14: 1.8044713 | T14: 1.8392071 | W14: 1.3770229 | X14: 0.36854849 | Y14: 63.308935 | Z14: 1.3004658 | AA14: 20.141575 | AB14: =SUM(C14:AA14) -> 2652.7836 | AG14: 17.010001
B15: 2018-2050 | C15: 1.8059701 | D15: 218.41791 | E15: 1190.3881 | F15: 0.10447761 | G15: 0.62686567 | H15: 15.820896 | I15: 11.134328 | J15: 34.328358 | K15: =$AG15*AI$35 -> 12.618657 | L15: =$AG15*AJ$35 -> 9.208209 | M15: =$AG15*AK$35 -> 7.5029851 | N15: =$AG15*AL$35 -> 2.7283582 | O15: =$AG15*AM$35 -> 2.0462687 | P15: 0 | Q15: 5.358209 | R15: 0.47761194 | S15: 2.4029851 | T15: 0.92537313 | U15: 82.910448 | V15: 0 | W15: 0.11940299 | X15: 1.3731343 | Y15: 25.686567 | Z15: 0.044776119 | AA15: 99.507463 | AB15: =SUM(C15:AA15) -> 1725.5373 | AG15: 34.104478
A16: Terraced | B16: 0-1945 | C16: 0.37854946 | D16: 162.86606 | E16: 1144.3173 | F16: 0 | G16: 0.018924161 | H16: 7.6938449 | I16: 0.23043419 | J16: 64.768413 | K16: =$AG16*AI$35 -> 4.8911125 | L16: =$AG16*AJ$35 -> 3.5691902 | M16: =$AG16*AK$35 -> 2.9082291 | N16: =$AG16*AL$35 -> 1.0575378 | O16: =$AG16*AM$35 -> 0.79315338 | P16: 263.36175 | Q16: 2.7625527 | R16: 0.3514936 | S16: 0.81826994 | T16: 1.3552015 | W16: 1.469714 | X16: 0 | Y16: 51.236411 | Z16: 0.43873776 | AA16: 25.673779 | AB16: =SUM(C16:AA16) -> 1740.9606 | AG16: 13.219223
B17: 1946-1974 | C17: {=(25/30)*Building_MI_original_baseline!C17:AA17+(5/30)*Building_MI_original_baseline!C18:AA18} -> 0.45919951 | D17: 146.57946 | E17: 1238.7901 | F17: 0 | G17: 0.018924161 | H17: 16.722917 | I17: 2.6610481 | J17: 37.434904 | K17: 5.009172 | L17: 3.6553417 | M17: 2.9784266 | N17: 1.0830642 | O17: 0.81229816 | P17: 290.68927 | Q17: 2.7625527 | R17: 0.3514936 | S17: 1.2663895 | T17: 1.4637035 | U17: 0 | V17: 0 | W17: 1.5202925 | X17: 0.47785589 | Y17: 53.458639 | Z17: 0.56953657 | AA17: 25.673779 | AB17: =SUM(C17:AA17) -> 1834.4383 | AG17: 13.477311
B18: 1975-2005 | C18: {=(25/30)*Building_MI_original_baseline!C18:AA18+(5/30)*Building_MI_original_baseline!C19:AA19} -> 0.37808582 | D18: 65.146426 | E18: 1304.4812 | F18: 0 | G18: 0.018924161 | H18: 16.722917 | I18: 4.3972009 | J18: 22.392487 | K18: 5.1915102 | L18: 3.7883993 | M18: 3.0868439 | N18: 1.1224887 | O18: 0.84186652 | P18: 427.32687 | Q18: 2.7625527 | R18: 0.3514936 | S18: 1.871411 | T18: 1.4762391 | U18: 0 | V18: 0 | W18: 1.5202925 | X18: 0.47785589 | Y18: 54.822602 | Z18: 1.2235306 | AA18: 25.673779 | AB18: =SUM(C18:AA18) -> 1945.075 | AG18: 13.843262
B19: 2006-2022 | C19: 0.37808582 | D19: 65.146426 | E19: 1304.4812 | F19: 0 | G19: 0.018924161 | H19: 16.722917 | I19: 4.3972009 | J19: 32.834915 | K19: =$AG19*AI$35 -> 5.5390262 | L19: =$AG19*AJ$35 -> 4.0419921 | M19: =$AG19*AK$35 -> 3.293475 | N19: =$AG19*AL$35 -> 1.1976273 | O19: =$AG19*AM$35 -> 0.89822047 | P19: 427.32687 | Q19: 2.7625527 | R19: 0.3514936 | S19: 1.871411 | T19: 1.556601 | W19: 1.5202925 | X19: 0.47785589 | Y19: 54.810217 | Z19: 1.2235306 | AA19: 25.673779 | AB19: =SUM(C19:AA19) -> 1956.5246 | AG19: 14.970341
B20: 2018-2050 | C20: 1.1980676 | D20: 179.96618 | E20: 1662.6232 | F20: 0.64251208 | G20: 0.89855072 | H20: 13.541063 | I20: 7.5458937 | J20: 24.903382 | K20: =$AG20*AI$35 -> 9.7737198 | L20: =$AG20*AJ$35 -> 7.1321739 | M20: =$AG20*AK$35 -> 5.811401 | N20: =$AG20*AL$35 -> 2.1132367 | O20: =$AG20*AM$35 -> 1.5849275 | P20: 0 | Q20: 6.5748792 | R20: 0.58454106 | S20: 2.8743961 | T20: 0.78743961 | U20: 63.603865 | V20: 0 | W20: 0.12077295 | X20: 0.58454106 | Y20: 29.855072 | Z20: 0.096618357 | AA20: 128.72947 | AB20: =SUM(C20:AA20) -> 2151.5459 | AG20: 26.415459
A21: Apartment building | B21: 0-1945 | C21: 0.2022183 | D21: 169.9378 | E21: 1421.6139 | F21: 0 | G21: 0.032032279 | H21: 13.986689 | I21: 0.23152289 | J21: 33.943423 | K21: =$AG21*AI$35 -> 6.8289593 | L21: =$AG21*AJ$35 -> 4.9832947 | M21: =$AG21*AK$35 -> 4.0604623 | N21: =$AG21*AL$35 -> 1.4765317 | O21: =$AG21*AM$35 -> 1.1073988 | P21: 224.76978 | Q21: 12.270727 | R21: 0.30749103 | S21: 0.99483574 | T21: 2.0525548 | W21: 0.72710812 | X21: 0 | Y21: 69.102116 | Z21: 0.83496119 | AA21: 16.468138 | AB21: =SUM(C21:AA21) -> 1985.932 | AG21: 18.456647
B22: 1946-1974 | C22: {=(25/30)*Building_MI_original_baseline!C22:AA22+(5/30)*Building_MI_original_baseline!C23:AA23} -> 0.30659409 | D22: 150.7074 | E22: 1514.6211 | F22: 0.1376447 | G22: 0.032032279 | H22: 13.822344 | I22: 2.9457613 | J22: 21.144124 | K22: 6.7453931 | L22: 4.9223139 | M22: 4.0107743 | N22: 1.4584634 | O22: 1.0938475 | P22: 241.44039 | Q22: 11.175228 | R22: 0.30764778 | S22: 1.338394 | T22: 5.6162251 | U22: 0 | V22: 0 | W22: 0.74128453 | X22: 0.35798067 | Y22: 68.932509 | Z22: 0.73466772 | AA22: 16.468138 | AB22: =SUM(C22:AA22) -> 2069.0602 | AG22: 19.158717
B23: 1975-2005 | C23: {=(25/30)*Building_MI_original_baseline!C23:AA23+(5/30)*Building_MI_original_baseline!C24:AA24} -> 0.78220972 | D23: 54.555367 | E23: 1526.4957 | F23: 0.8258682 | G23: 0.032032279 | H23: 13.00062 | I23: 4.8845031 | J23: 12.026846 | K23: 4.8355059 | L23: 3.5286124 | M23: 2.8751657 | N23: 1.0455148 | O23: 0.78413609 | P23: 324.79346 | Q23: 5.6977324 | R23: 0.3085099 | S23: 1.8858516 | T23: 5.605894 | U23: 0 | V23: 0 | W23: 0.74693622 | X23: 0.35798067 | Y23: 70.660171 | Z23: 0.88796921 | AA23: 16.468138 | AB23: =SUM(C23:AA23) -> 2053.0847 | AG23: 13.591166
B24: 2006-2022 | C24: 0.78220972 | D24: 54.555367 | E24: 1526.4957 | F24: 0.8258682 | G24: 0.032032279 | H24: 13.00062 | I24: 4.8845031 | J24: 13.12516 | K24: =$AG24*AI$35 -> 3.8693782 | L24: =$AG24*AJ$35 -> 2.8236003 | M24: =$AG24*AK$35 -> 2.3007113 | N24: =$AG24*AL$35 -> 0.83662231 | O24: =$AG24*AM$35 -> 0.62746673 | P24: 324.79346 | Q24: 5.6977324 | R24: 0.30890178 | S24: 1.8877069 | T24: 5.5541377 | W24: 0.74699402 | X24: 0.35798067 | Y24: 70.647257 | Z24: 0.88796921 | AA24: 16.468138 | AB24: =SUM(C24:AA24) -> 2051.5095 | AG24: 10.457779
B25: 2018-2050 | C25: 1.548913 | D25: 237.06522 | E25: 1107.9076 | F25: 0.31521739 | G25: 1.2880435 | H25: 30.875 | I25: 5.8913043 | J25: 2.2065217 | K25: =$AG25*AI$35 -> 2.851413 | L25: =$AG25*AJ$35 -> 2.0807609 | M25: =$AG25*AK$35 -> 1.6954348 | N25: =$AG25*AL$35 -> 0.61652174 | O25: =$AG25*AM$35 -> 0.4623913 | P25: 0 | Q25: 12.581522 | R25: 0.375 | S25: 2.5054348 | T25: 0.99456522 | U25: 61.532609 | V25: 0 | W25: 0.125 | X25: 0.27173913 | Y25: 21.673913 | Z25: 0.5326087 | AA25: 30.11413 | AB25: =SUM(C25:AA25) -> 1525.5109 | AG25: 7.7065217
A26: Mixed-Use | B26: 0-1945 | C26: 0.11701019 | D26: 171.36517 | E26: 1097.8571 | F26: 0.067692308 | G26: 0.036630036 | H26: 9.5043092 | I26: 11.018225 | J26: 42.832492 | K26: =$AG26*AI$35 -> 6.2467805 | L26: =$AG26*AJ$35 -> 4.5584615 | M26: =$AG26*AK$35 -> 3.7143019 | N26: =$AG26*AL$35 -> 1.3506552 | O26: =$AG26*AM$35 -> 1.0129914 | P26: 252.87194 | Q26: 18.818937 | R26: 0.20715254 | S26: 1.4989691 | T26: 1.974297 | W26: 0.46113915 | X26: 0 | Y26: 46.466515 | Z26: 0.050542407 | AA26: 13.502395 | AB26: =SUM(C26:AA26) -> 1685.5337 | AG26: 16.883191
B27: 1946-1974 | C27: {=(25/30)*Building_MI_original_baseline!C27:AA27+(5/30)*Building_MI_original_baseline!C28:AA28} -> 0.3543056 | D27: 154.22866 | E27: 1175.5815 | F27: 0.056410256 | G27: 0.036630036 | H27: 9.6854362 | I27: 14.681625 | J27: 21.920455 | K27: 6.0672767 | L27: 4.4274722 | M27: 3.6075699 | N27: 1.3118436 | O27: 0.98388271 | P27: 267.21638 | Q27: 16.489943 | R27: 0.20721356 | S27: 1.7784211 | T27: 2.6960069 | U27: 0 | V27: 0 | W27: 0.4949922 | X27: 0.43177826 | Y27: 46.813977 | Z27: 0.015460693 | AA27: 13.502395 | AB27: =SUM(C27:AA27) -> 1742.5896 | AG27: 17.205953
B28: 1975-2005 | C28: {=(25/30)*Building_MI_original_baseline!C28:AA28+(5/30)*Building_MI_original_baseline!C29:AA29} -> 1.4720486 | D28: 68.546069 | E28: 1208.6321 | F28: 0 | G28: 0.036630036 | H28: 10.591071 | I28: 17.29834 | J28: 10.256356 | K28: 4.3356497 | L28: 3.1638525 | M28: 2.5779539 | N28: 0.93743777 | O28: 0.70307833 | P28: 338.93859 | Q28: 4.8449722 | R28: 0.20754915 | S28: 1.8116663 | T28: 2.6605954 | U28: 0 | V28: 0 | W28: 0.4949922 | X28: 0.43177826 | Y28: 48.053938 | Z28: 0.092764159 | AA28: 13.502395 | AB28: =SUM(C28:AA28) -> 1739.5898 | AG28: 12.358509
B29: 2006-2022 | C29: 1.4741659 | D29: 68.546069 | E29: 1208.6321 | F29: 0 | G29: 0.036630036 | H29: 10.591071 | I29: 17.29834 | J29: 14.176483 | K29: =$AG29*AI$35 -> 3.1506568 | L29: =$AG29*AJ$35 -> 2.299128 | M29: =$AG29*AK$35 -> 1.8733635 | N29: =$AG29*AL$35 -> 0.6812231 | O29: =$AG29*AM$35 -> 0.51091732 | P29: 338.93859 | Q29: 4.8449722 | R29: 0.20770169 | S29: 1.8127363 | T29: 2.6451738 | W29: 0.4949922 | X29: 0.43177826 | Y29: 48.049123 | Z29: 0.092764159 | AA29: 13.502395 | AB29: =SUM(C29:AA29) -> 1740.2904 | AG29: 8.5152887
B30: 2018-2050 | C30: 1.4725275 | D30: 68.549451 | E30: 1178.1319 | F30: 0 | G30: 0.032967033 | H30: 10.791209 | I30: 17.296703 | J30: 16 | K30: =$AG30*AI$35 -> 3.3991209 | L30: =$AG30*AJ$35 -> 2.4804396 | M30: =$AG30*AK$35 -> 2.0210989 | N30: =$AG30*AL$35 -> 0.73494505 | O30: =$AG30*AM$35 -> 0.55120879 | P30: 338.93407 | Q30: 5.2527473 | R30: 0.20879121 | S30: 1.8131868 | T30: 2.6483516 | U30: 30.505495 | V30: 1.2307692 | W30: 0.49450549 | X30: 0.42857143 | Y30: 48.065934 | Z30: 0.087912088 | AA30: 13.505495 | AB30: =SUM(C30:AA30) -> 1744.6374 | AG30: 9.1868132
AI34: Glass wool | AJ34: Expanded polystyrene | AK34: Stone wool | AL34: Polyurethanes | AM34: Extruded polystyrene | AN34: Biobased (wooden fibre board or flaxwool )
AG35: Stock | AI35: 0.37 | AJ35: 0.27 | AK35: 0.22 | AL35: 0.08 | AM35: 0.06
AG36: Construction | AH36: Conventional | AI36: 0.37 | AJ36: 0.27 | AK36: 0.22 | AL36: 0.08 | AM36: 0.06
AH37: Circular | AI37: 0.37 | AK37: 0.3 | AN37: 0.33
AH38: Biobased | AI38: 0.37 | AK38: 0.22 | AN38: =0.14+0.27 -> 0.41
A45: Meta Data | D45: file name
A46: Source | B46: Oorschot et al. 2023
A47: Empirical historic data | B47: MPG | C47: Metabolic data analyis | D47: historic_MI­_original
A48: Future model | B48: Metabolic | C48: Baseline in Oorschot analysis | D48: Metabolic_MI_scenarios_21102021

Sheet Building_MI_original_baseline
C1: kg/m2 UFA | D1: kg/m2 UFA | E1: kg/m2 UFA | F1: kg/m2 UFA | G1: kg/m2 UFA | H1: kg/m2 UFA | I1: kg/m2 UFA | J1: kg/m2 UFA | K1: kg/m2 UFA | L1: kg/m2 UFA | M1: kg/m2 UFA | N1: kg/m2 UFA | O1: kg/m2 UFA | P1: kg/m2 UFA | Q1: kg/m2 UFA | R1: kg/m2 UFA | S1: kg/m2 UFA | T1: kg/m2 UFA | U1: kg/m2 UFA | V1: kg/m2 UFA | W1: kg/m2 UFA | X1: kg/m2 UFA | Y1: kg/m2 UFA | Z1: kg/m2 UFA | AA1: kg/m2 UFA | AG1: kg/m2 UFA
A2: Treatment | B2: BONSAI Waste | C2: M_wAlum | D2: M_wCons | E2: M_wCons | F2: M_wCons | G2: M_wDisc_eq | H2: M_wCons | I2: M_wGlas | J2: M_wWood | K2: M_wCons | L2: M_wCons | M2: M_wCons | N2: M_wCons | O2: M_wCons | P2: M_wCons | Q2: M_wCons | R2: M_wCopp | S2: M_wPlas | T2: M_wCons | U2: M_wCons | V2: M_wWood | W2: M_wMix_nonferr | X2: M_wPape | Y2: M_wStel | Z2: M_wCons | AA2: M_wCons
B3: BONSAI_2nd | F3: M_CMNT | Q3: M_CRMC | S3: M_PLAS | W3: M_ONFM | Y3: M_STEL
A4: Cradle-to-gate | B4: BONSAI | C4: M_ALUM | D4: M_BRIK | E4: M_CMNT + M_SDCL | F4: M_BITU | G4: M_ELMA | H4: M_BRIK | I4: M_GLAS | J4: M_WOOD | K4: M_GLAS | L4: M_RUBP | M4: M_ONMM | N4: M_RUBP | O4: M_RUBP | P4: M_BRIK | Q4: M_BRIK | R4: M_COPP | S4: M_RUBP | T4: M_CHEM | U4: M_BRIK | V4: M_WOOD | W4: M_LZTP | X4: M_PAPE | Y4: M_FABM | Z4: M_STON | AA4: M_SDCL
A5: Building type | B5: Building age | C5: Aluminium (kg/m2) | D5: Baksteen (kg/m2) | E5: Beton (kg/m2) | F5: Bitumen (kg/m2) | G5: Electronica (kg/m2) | H5: Gips (kg/m2) | I5: Glas (kg/m2) | J5: Hout (kg/m2) | K5: Glass wool | L5: Expanded polystyrene | M5: Stone wool | N5: Polyurethanes | O5: Extruded polystyrene | P5: Kalkzandsteen (kg/m2) | Q5: Keramiek (kg/m2) | R5: Koper (kg/m2) | S5: Kunststoffen (kg/m2) | T5: Lijm en verf (kg/m2) | U5: Mortel | V5: Overig biobased | W5: Overige metalen (kg/m2) | X5: Papier (kg/m2) | Y5: Staal & IJzer (kg/m2) | Z5: Steen (kg/m2) | AA5: Zand (kg/m2) | AB5: TOTAL | AG5: Isolatie (kg/m2)
A6: Detached | B6: pre 1945 | C6: 0.11230813 | D6: 290.13366 | E6: 1376.7649 | F6: 0 | G6: 0.014084507 | H6: 9.3222155 | I6: 0 | J6: 181.00587 | K6: =$AG6*AI$35 -> 5.0229685 | L6: =$AG6*AJ$35 -> 3.6654095 | M6: =$AG6*AK$35 -> 2.9866299 | N6: =$AG6*AL$35 -> 1.0860472 | O6: =$AG6*AM$35 -> 0.81453543 | P6: 307.73568 | Q6: 33.736131 | R6: 0.91964414 | S6: 1.3289144 | T6: 1.5227198 | W6: 3.9420607 | X6: 0 | Y6: 69.751482 | Z6: 22.052395 | AA6: 25.486251 | AB6: =SUM(C6:AA6) -> 2337.4039 | AG6: 13.575591
B7: 1945-1970 | C7: 0.20712039 | D7: 290.13366 | E7: 1375.8506 | F7: 0 | G7: 0.014084507 | H7: 31.410363 | I7: 3.2294998 | J7: 98.419572 | K7: =$AG7*AI$35 -> 5.19251 | L7: =$AG7*AJ$35 -> 3.7891289 | M7: =$AG7*AK$35 -> 3.0874384 | N7: =$AG7*AL$35 -> 1.1227049 | O7: =$AG7*AM$35 -> 0.84202865 | P7: 307.73568 | Q7: 33.736131 | R7: 0.91964414 | S7: 1.5755942 | T7: 1.5071152 | W7: 3.9451693 | X7: 0.2419383 | Y7: 56.706149 | Z7: 22.052395 | AA7: 25.486251 | AB7: =SUM(C7:AA7) -> 2267.2048 | AG7: 14.033811
B8: 1970-2000 | C8: 0.19397869 | D8: 116.05346 | E8: 1310.8141 | F8: 0.23186739 | G8: 0.014084507 | H8: 31.410363 | I8: 6.4589995 | J8: 25.12355 | K8: =$AG8*AI$35 -> 5.4177443 | L8: =$AG8*AJ$35 -> 3.9534891 | M8: =$AG8*AK$35 -> 3.2213615 | N8: =$AG8*AL$35 -> 1.1714042 | O8: =$AG8*AM$35 -> 0.87855313 | P8: 655.38373 | Q8: 2.3478011 | R8: 0.91964414 | S8: 1.7965502 | T8: 1.4728023 | W8: 3.9451693 | X8: 0.2419383 | Y8: 44.199921 | Z8: 23.182847 | AA8: 25.486251 | AB8: =SUM(C8:AA8) -> 2263.9196 | AG8: 14.642552
B9: 2000-2018 | C9: 0.19397869 | D9: 116.05346 | E9: 1310.8141 | F9: 0.23186739 | G9: 0.014084507 | H9: 31.410363 | I9: 6.4589995 | J9: 35.69002 | K9: =$AG9*AI$35 -> 6.1029226 | L9: =$AG9*AJ$35 -> 4.4534841 | M9: =$AG9*AK$35 -> 3.6287648 | N9: =$AG9*AL$35 -> 1.3195508 | O9: =$AG9*AM$35 -> 0.98966312 | P9: 655.38373 | Q9: 2.3478011 | R9: 0.91964414 | S9: 1.7965502 | T9: 1.5506931 | W9: 3.9451693 | X9: 0.2419383 | Y9: 44.186521 | Z9: 23.182847 | AA9: 25.486251 | AB9: 2276.4024 | AG9: 16.494385
B10: 2018-2050 | C10: 1.8059701 | D10: 218.41791 | E10: 1190.3881 | F10: 0.10447761 | G10: 0.62686567 | H10: 15.820896 | I10: 11.134328 | J10: 34.328358 | K10: =$AG10*AI$35 -> 12.618657 | L10: =$AG10*AJ$35 -> 9.208209 | M10: =$AG10*AK$35 -> 7.5029851 | N10: =$AG10*AL$35 -> 2.7283582 | O10: =$AG10*AM$35 -> 2.0462687 | P10: 0 | Q10: 5.358209 | R10: 0.47761194 | S10: 2.4029851 | T10: 0.92537313 | U10: 82.910448 | V10: 0 | W10: 0.11940299 | X10: 1.3731343 | Y10: 25.686567 | Z10: 0.044776119 | AA10: 99.507463 | AB10: =SUM(C10:AA10) -> 1725.5373 | AG10: 34.104478
A11: Semi-Detached | B11: pre 1945 | C11: 0.18886813 | D11: 322.16942 | E11: 1388.6241 | F11: 0 | G11: 0.0070422535 | H11: 10.021588 | I11: 0.18055071 | J11: 88.178593 | K11: =$AG11*AI$35 -> 5.3200697 | L11: =$AG11*AJ$35 -> 3.882213 | M11: =$AG11*AK$35 -> 3.1632847 | N11: =$AG11*AL$35 -> 1.1502853 | O11: =$AG11*AM$35 -> 0.862714 | P11: 327.72171 | Q11: 3.3205046 | R11: 0.84813829 | S11: 1.2349096 | T11: 1.6288592 | W11: 1.3351706 | X11: 0 | Y11: 59.321163 | Z11: 0.47078742 | AA11: 20.141575 | AB11: =SUM(C11:AA11) -> 2239.7716 | AG11: 14.378567
B12: 1945-1970 | C12: 0.28762023 | D12: 322.16942 | E12: 1508.2651 | F12: 0 | G12: 0.0070422535 | H12: 46.677547 | I12: 2.4917772 | J12: 52.547994 | K12: =$AG12*AI$35 -> 5.5080911 | L12: =$AG12*AJ$35 -> 4.0194179 | M12: =$AG12*AK$35 -> 3.2750812 | N12: =$AG12*AL$35 -> 1.1909386 | O12: =$AG12*AM$35 -> 0.89320397 | P12: 327.72171 | Q12: 3.3205046 | R12: 0.84813829 | S12: 1.5494636 | T12: 1.7200034 | W12: 1.3770229 | X12: 0.36854849 | Y12: 61.458933 | Z12: 0.47078742 | AA12: 20.141575 | AB12: =SUM(C12:AA12) -> 2366.3099 | AG12: 14.886733
B13: 1970-2000 | C13: 0.25258703 | D13: 128.86777 | E13: 1589.9202 | F13: 0 | G13: 0.0070422535 | H13: 46.677547 | I13: 4.8030037 | J13: 28.588292 | K13: =$AG13*AI$35 -> 5.6976004 | L13: =$AG13*AJ$35 -> 4.1577084 | M13: =$AG13*AK$35 -> 3.3877624 | N13: =$AG13*AL$35 -> 1.2319136 | O13: =$AG13*AM$35 -> 0.9239352 | P13: 728.52222 | Q13: 3.3205046 | R13: 0.84813829 | S13: 1.8044713 | T13: 1.7337558 | W13: 1.3770229 | X13: 0.36854849 | Y13: 63.325574 | Z13: 1.3004658 | AA13: 20.141575 | AB13: =SUM(C13:AA13) -> 2637.2576 | AG13: 15.39892
B14: 2000-2018 | C14: 0.25258703 | D14: 128.86777 | E14: 1589.9202 | F14: 0 | G14: 0.0070422535 | H14: 46.677547 | I14: 4.8030037 | J14: 42.414407 | K14: =$AG14*AI$35 -> 6.2937005 | L14: =$AG14*AJ$35 -> 4.5927004 | M14: =$AG14*AK$35 -> 3.7422003 | N14: =$AG14*AL$35 -> 1.3608001 | O14: =$AG14*AM$35 -> 1.0206001 | P14: 728.52222 | Q14: 3.3205046 | R14: 0.84813829 | S14: 1.8044713 | T14: 1.8392071 | W14: 1.3770229 | X14: 0.36854849 | Y14: 63.308935 | Z14: 1.3004658 | AA14: 20.141575 | AB14: 2652.7836 | AG14: 17.010001
B15: 2018-2050 | C15: 1.8059701 | D15: 218.41791 | E15: 1190.3881 | F15: 0.10447761 | G15: 0.62686567 | H15: 15.820896 | I15: 11.134328 | J15: 34.328358 | K15: =$AG15*AI$35 -> 12.618657 | L15: =$AG15*AJ$35 -> 9.208209 | M15: =$AG15*AK$35 -> 7.5029851 | N15: =$AG15*AL$35 -> 2.7283582 | O15: =$AG15*AM$35 -> 2.0462687 | P15: 0 | Q15: 5.358209 | R15: 0.47761194 | S15: 2.4029851 | T15: 0.92537313 | U15: 82.910448 | V15: 0 | W15: 0.11940299 | X15: 1.3731343 | Y15: 25.686567 | Z15: 0.044776119 | AA15: 99.507463 | AB15: =SUM(C15:AA15) -> 1725.5373 | AG15: 34.104478
A16: Terraced | B16: pre 1945 | C16: 0.37854946 | D16: 162.86606 | E16: 1144.3173 | F16: 0 | G16: 0.018924161 | H16: 7.6938449 | I16: 0.23043419 | J16: 64.768413 | K16: =$AG16*AI$35 -> 4.8911125 | L16: =$AG16*AJ$35 -> 3.5691902 | M16: =$AG16*AK$35 -> 2.9082291 | N16: =$AG16*AL$35 -> 1.0575378 | O16: =$AG16*AM$35 -> 0.79315338 | P16: 263.36175 | Q16: 2.7625527 | R16: 0.3514936 | S16: 0.81826994 | T16: 1.3552015 | W16: 1.469714 | X16: 0 | Y16: 51.236411 | Z16: 0.43873776 | AA16: 25.673779 | AB16: =SUM(C16:AA16) -> 1740.9606 | AG16: 13.219223
B17: 1945-1970 | C17: 0.47542225 | D17: 162.86606 | E17: 1225.6518 | F17: 0 | G17: 0.018924161 | H17: 16.722917 | I17: 2.3138175 | J17: 40.861085 | K17: =$AG17*AI$35 -> 4.986605 | L17: =$AG17*AJ$35 -> 3.6388739 | M17: =$AG17*AK$35 -> 2.9650084 | N17: =$AG17*AL$35 -> 1.0781849 | O17: =$AG17*AM$35 -> 0.80863865 | P17: 263.36175 | Q17: 2.7625527 | R17: 0.3514936 | S17: 1.1453852 | T17: 1.4644108 | W17: 1.5202925 | X17: 0.47785589 | Y17: 53.185351 | Z17: 0.43873776 | AA17: 25.673779 | AB17: =SUM(C17:AA17) -> 1812.769 | AG17: 13.477311
B18: 1970-2000 | C18: 0.37808582 | D18: 65.146426 | E18: 1304.4812 | F18: 0 | G18: 0.018924161 | H18: 16.722917 | I18: 4.3972009 | J18: 20.304001 | K18: =$AG18*AI$35 -> 5.122007 | L18: =$AG18*AJ$35 -> 3.7376808 | M18: =$AG18*AK$35 -> 3.0455177 | N18: =$AG18*AL$35 -> 1.107461 | O18: =$AG18*AM$35 -> 0.83059573 | P18: 427.32687 | Q18: 2.7625527 | R18: 0.3514936 | S18: 1.871411 | T18: 1.4601667 | W18: 1.5202925 | X18: 0.47785589 | Y18: 54.825079 | Z18: 1.2235306 | AA18: 25.673779 | AB18: =SUM(C18:AA18) -> 1942.7851 | AG18: 13.843262
B19: 2000-2018 | C19: 0.37808582 | D19: 65.146426 | E19: 1304.4812 | F19: 0 | G19: 0.018924161 | H19: 16.722917 | I19: 4.3972009 | J19: 32.834915 | K19: =$AG19*AI$35 -> 5.5390262 | L19: =$AG19*AJ$35 -> 4.0419921 | M19: =$AG19*AK$35 -> 3.293475 | N19: =$AG19*AL$35 -> 1.1976273 | O19: =$AG19*AM$35 -> 0.89822047 | P19: 427.32687 | Q19: 2.7625527 | R19: 0.3514936 | S19: 1.871411 | T19: 1.556601 | W19: 1.5202925 | X19: 0.47785589 | Y19: 54.810217 | Z19: 1.2235306 | AA19: 25.673779 | AB19: 1956.5246 | AG19: 14.970341
B20: 2018-2050 | C20: 1.1980676 | D20: 179.96618 | E20: 1662.6232 | F20: 0.64251208 | G20: 0.89855072 | H20: 13.541063 | I20: 7.5458937 | J20: 24.903382 | K20: =$AG20*AI$35 -> 9.7737198 | L20: =$AG20*AJ$35 -> 7.1321739 | M20: =$AG20*AK$35 -> 5.811401 | N20: =$AG20*AL$35 -> 2.1132367 | O20: =$AG20*AM$35 -> 1.5849275 | P20: 0 | Q20: 6.5748792 | R20: 0.58454106 | S20: 2.8743961 | T20: 0.78743961 | U20: 63.603865 | V20: 0 | W20: 0.12077295 | X20: 0.58454106 | Y20: 29.855072 | Z20: 0.096618357 | AA20: 128.72947 | AB20: =SUM(C20:AA20) -> 2151.5459 | AG20: 26.415459
A21: Apartment building | B21: pre 1945 | C21: 0.2022183 | D21: 169.9378 | E21: 1421.6139 | F21: 0 | G21: 0.032032279 | H21: 13.986689 | I21: 0.23152289 | J21: 33.943423 | K21: =$AG21*AI$35 -> 6.8289593 | L21: =$AG21*AJ$35 -> 4.9832947 | M21: =$AG21*AK$35 -> 4.0604623 | N21: =$AG21*AL$35 -> 1.4765317 | O21: =$AG21*AM$35 -> 1.1073988 | P21: 224.76978 | Q21: 12.270727 | R21: 0.30749103 | S21: 0.99483574 | T21: 2.0525548 | W21: 0.72710812 | X21: 0 | Y21: 69.102116 | Z21: 0.83496119 | AA21: 16.468138 | AB21: =SUM(C21:AA21) -> 1985.932 | AG21: 18.456647
B22: 1945-1970 | C22: 0.21147097 | D22: 169.9378 | E22: 1512.2462 | F22: 0 | G22: 0.032032279 | H22: 13.986689 | I22: 2.558013 | J22: 23.011512 | K22: =$AG22*AI$35 -> 7.0887254 | L22: =$AG22*AJ$35 -> 5.1728537 | M22: =$AG22*AK$35 -> 4.2149178 | N22: =$AG22*AL$35 -> 1.5326974 | O22: =$AG22*AM$35 -> 1.149523 | P22: 224.76978 | Q22: 12.270727 | R22: 0.30749103 | S22: 1.2289767 | T22: 5.6162211 | W22: 0.7401565 | X22: 0.35798067 | Y22: 68.58646 | Z22: 0.70400743 | AA22: 16.468138 | AB22: =SUM(C22:AA22) -> 2072.1923 | AG22: 19.158717
B23: 1970-2000 | C23: 0.78220972 | D23: 54.555367 | E23: 1526.4957 | F23: 0.8258682 | G23: 0.032032279 | H23: 13.00062 | I23: 4.8845031 | J23: 11.807183 | K23: =$AG23*AI$35 -> 5.0287314 | L23: =$AG23*AJ$35 -> 3.6696148 | M23: =$AG23*AK$35 -> 2.9900565 | N23: =$AG23*AL$35 -> 1.0872933 | O23: =$AG23*AM$35 -> 0.81546996 | P23: 324.79346 | Q23: 5.6977324 | R23: 0.30843153 | S23: 1.8854806 | T23: 5.6162452 | W23: 0.74692466 | X23: 0.35798067 | Y23: 70.662754 | Z23: 0.88796921 | AA23: 16.468138 | AB23: =SUM(C23:AA23) -> 2053.3998 | AG23: 13.591166
B24: 2000-2018 | C24: 0.78220972 | D24: 54.555367 | E24: 1526.4957 | F24: 0.8258682 | G24: 0.032032279 | H24: 13.00062 | I24: 4.8845031 | J24: 13.12516 | K24: =$AG24*AI$35 -> 3.8693782 | L24: =$AG24*AJ$35 -> 2.8236003 | M24: =$AG24*AK$35 -> 2.3007113 | N24: =$AG24*AL$35 -> 0.83662231 | O24: =$AG24*AM$35 -> 0.62746673 | P24: 324.79346 | Q24: 5.6977324 | R24: 0.30890178 | S24: 1.8877069 | T24: 5.5541377 | W24: 0.74699402 | X24: 0.35798067 | Y24: 70.647257 | Z24: 0.88796921 | AA24: 16.468138 | AB24: 2051.5095 | AG24: 10.457779
B25: 2018-2050 | C25: 1.548913 | D25: 237.06522 | E25: 1107.9076 | F25: 0.31521739 | G25: 1.2880435 | H25: 30.875 | I25: 5.8913043 | J25: 2.2065217 | K25: =$AG25*AI$35 -> 2.851413 | L25: =$AG25*AJ$35 -> 2.0807609 | M25: =$AG25*AK$35 -> 1.6954348 | N25: =$AG25*AL$35 -> 0.61652174 | O25: =$AG25*AM$35 -> 0.4623913 | P25: 0 | Q25: 12.581522 | R25: 0.375 | S25: 2.5054348 | T25: 0.99456522 | U25: 61.532609 | V25: 0 | W25: 0.125 | X25: 0.27173913 | Y25: 21.673913 | Z25: 0.5326087 | AA25: 30.11413 | AB25: =SUM(C25:AA25) -> 1525.5109 | AG25: 7.7065217
A26: Mixed-Use | B26: pre 1945 | C26: 0.11701019 | D26: 171.36517 | E26: 1097.8571 | F26: 0.067692308 | G26: 0.036630036 | H26: 9.5043092 | I26: 11.018225 | J26: 42.832492 | K26: =$AG26*AI$35 -> 6.2467805 | L26: =$AG26*AJ$35 -> 4.5584615 | M26: =$AG26*AK$35 -> 3.7143019 | N26: =$AG26*AL$35 -> 1.3506552 | O26: =$AG26*AM$35 -> 1.0129914 | P26: 252.87194 | Q26: 18.818937 | R26: 0.20715254 | S26: 1.4989691 | T26: 1.974297 | W26: 0.46113915 | X26: 0 | Y26: 46.466515 | Z26: 0.050542407 | AA26: 13.502395 | AB26: =SUM(C26:AA26) -> 1685.5337 | AG26: 16.883191
B27: 1945-1970 | C27: 0.1308417 | D27: 171.36517 | E27: 1168.9714 | F27: 0.067692308 | G27: 0.036630036 | H27: 9.5043092 | I27: 14.158282 | J27: 24.410079 | K27: =$AG27*AI$35 -> 6.3662024 | L27: =$AG27*AJ$35 -> 4.6456072 | M27: =$AG27*AK$35 -> 3.7853096 | N27: =$AG27*AL$35 -> 1.3764762 | O27: =$AG27*AM$35 -> 1.0323572 | P27: 252.87194 | Q27: 18.818937 | R27: 0.20715254 | S27: 1.7718149 | T27: 2.7024723 | W27: 0.4949922 | X27: 0.43177826 | Y27: 46.565792 | Z27: 0 | AA27: 13.502395 | AB27: =SUM(C27:AA27) -> 1743.2176 | AG27: 17.205953
B28: 1970-2000 | C28: 1.4716251 | D28: 68.546069 | E28: 1208.6321 | F28: 0 | G28: 0.036630036 | H28: 10.591071 | I28: 17.29834 | J28: 9.4723306 | K28: =$AG28*AI$35 -> 4.5726482 | L28: =$AG28*AJ$35 -> 3.3367974 | M28: =$AG28*AK$35 -> 2.7188719 | N28: =$AG28*AL$35 -> 0.9886807 | O28: =$AG28*AM$35 -> 0.74151053 | P28: 338.93859 | Q28: 4.8449722 | R28: 0.20751864 | S28: 1.8114522 | T28: 2.6636797 | W28: 0.4949922 | X28: 0.43177826 | Y28: 48.054901 | Z28: 0.092764159 | AA28: 13.502395 | AB28: =SUM(C28:AA28) -> 1739.4497 | AG28: 12.358509
B29: 2000-2018 | C29: 1.4741659 | D29: 68.546069 | E29: 1208.6321 | F29: 0 | G29: 0.036630036 | H29: 10.591071 | I29: 17.29834 | J29: 14.176483 | K29: =$AG29*AI$35 -> 3.1506568 | L29: =$AG29*AJ$35 -> 2.299128 | M29: =$AG29*AK$35 -> 1.8733635 | N29: =$AG29*AL$35 -> 0.6812231 | O29: =$AG29*AM$35 -> 0.51091732 | P29: 338.93859 | Q29: 4.8449722 | R29: 0.20770169 | S29: 1.8127363 | T29: 2.6451738 | W29: 0.4949922 | X29: 0.43177826 | Y29: 48.049123 | Z29: 0.092764159 | AA29: 13.502395 | AB29: 1740.2904 | AG29: 8.5152887
B30: 2018-2050 | C30: 1.4725275 | D30: 68.549451 | E30: 1178.1319 | F30: 0 | G30: 0.032967033 | H30: 10.791209 | I30: 17.296703 | J30: 16 | K30: =$AG30*AI$35 -> 3.3991209 | L30: =$AG30*AJ$35 -> 2.4804396 | M30: =$AG30*AK$35 -> 2.0210989 | N30: =$AG30*AL$35 -> 0.73494505 | O30: =$AG30*AM$35 -> 0.55120879 | P30: 338.93407 | Q30: 5.2527473 | R30: 0.20879121 | S30: 1.8131868 | T30: 2.6483516 | U30: 30.505495 | V30: 1.2307692 | W30: 0.49450549 | X30: 0.42857143 | Y30: 48.065934 | Z30: 0.087912088 | AA30: 13.505495 | AB30: =SUM(C30:AA30) -> 1744.6374 | AG30: 9.1868132
AI34: Glass wool | AJ34: Expanded polystyrene | AK34: Stone wool | AL34: Polyurethanes | AM34: Extruded polystyrene | AN34: Biobased (wooden fibre board or flaxwool )
AG35: Stock | AI35: 0.37 | AJ35: 0.27 | AK35: 0.22 | AL35: 0.08 | AM35: 0.06
AG36: Construction | AH36: Conventional | AI36: 0.37 | AJ36: 0.27 | AK36: 0.22 | AL36: 0.08 | AM36: 0.06
AH37: Circular | AI37: 0.37 | AK37: 0.3 | AN37: 0.33
AH38: Biobased | AI38: 0.37 | AK38: 0.22 | AN38: =0.14+0.27 -> 0.41
A45: Meta Data | D45: file name
A46: Source | B46: Oorschot et al. 2023
A47: Empirical historic data | B47: MPG | C47: Metabolic data analyis | D47: historic_MI­_original
A48: Future model | B48: Metabolic | C48: Baseline in Oorschot analysis | D48: Metabolic_MI_scenarios_21102021

Sheet MI_Info Case Studies
A2: BONSAI | B2: MPG | I2: Materials for which information is needed:
A3: M_ALUM | B3: Aluminium (kg/m2) | H3: Total weight of | I3: Concrete
A4: M_BRIK | B4: Baksteen (kg/m2) | H4: Total weight of | I4: Steel and iron
A5: M_BRIK | B5: Gips (kg/m2) | H5: Total weight of | I5: Bricks+Gips+Tiles+Mortar
A6: M_BRIK | B6: Kalkzandsteen (kg/m2) | H6: Total weight of | I6: Glass+Glass wool
A7: M_BRIK | B7: Keramiek (kg/m2) | H7: Total weight of | I7: Wood + other biobased materials including insulation
A8: M_BRIK | B8: Mortel | H8: Total weight of | I8: Plastics + EPS (expanded polystyrene) + XPS (extruded polystyrene) + PUR (polyurethane)
A9: M_CHEM | B9: Lijm en verf (kg/m2) | H9: Total weight of | I9: Rock wool
A10: M_CMNT | B10: Bitumen (kg/m2) | H10: Total weight of | I10: Bitumen
A11: M_CMNT + M_SDCL | B11: Beton (kg/m2) | H11: Total weight of | I11: Electronics
A12: M_COPP | B12: Koper (kg/m2) | H12: Total weight of | I12: Stone
A13: M_ELMA | B13: Electronica (kg/m2) | H13: Total weight of | I13: Sand
A14: M_FABM | B14: Staal & IJzer (kg/m2) | H14: Total weight of | I14: Aluminium
... A18: M_RUBP | B18: Kunststoffen (kg/m2) | H18: Total weight of | I18: Paper
A19: M_SDCL | B19: Zand (kg/m2)
A20: M_STON | B20: Steen (kg/m2)
A21: M_WOOD | B21: Hout (kg/m2)
A22: M_WOOD | B22: Overig biobased
A23: M_ONMM | B23: Stone wool
A27: Ökobaudat reference emission factors to match BONSAI sectors
A29: Gips | C29: Bitumen
A30: =-0.7+0.2+0.07+0.1+6.7+0.8-0.2 -> 6.97 | C30: =0.356+0.005+0.09 -> 0.451
A31: 0.26 | C31: =552*0.001 -> 0.552
A32: 0.21
A34: Mortar | D34: Paint
A35: 360 | B35: =A35/2000 -> 0.18 | D35: 2
A36: 230 | B36: =A36/1800 -> 0.12777778 | D36: 1.5
A37: 400 | B37: =A37/1800 -> 0.22222222 | D37: 1.4
A38: 435 | B38: =A38/1800 -> 0.24166667 | D38: 0.9
D39: 2.5
A40: Brick | D40: Beton
A41: 540 | B41: =A41/2000 -> 0.27 | D41: 170 | E41: =D41/2200 -> 0.077272727
A43: Stonewool | D43: Glaswoll
A44: 62 | B44: =A44/50 -> 1.24 | D44: 134 | E44: =D44/85 -> 1.5764706
A46: 70 | B46: =A46/46 -> 1.5217391 | D46: =40 -> 40 | E46: =D46/24 -> 1.6666667
A48: EPS | D48: XPS
A49: =605 -> 605 | B49: =A49/150 -> 4.0333333 | D49: =100/32 -> 3.125
A50: 60 | B50: =60/15 -> 4 | D50: =56/33 -> 1.6969697
A52: PUR
A53: 5.6
...

Sheet Classifications
A1: Building type | D1: Energy Merger | G1: Building age | M1: Energy Merger
A2: Oorschot et al. 2023 | B2: CBS Microdata | D2: TABULA | G2: Metabolic | H2: Oorschot et al. | L2: TABULA
A3: vrijstaande woningvilla zadeldak | B3: Detached | D3: Single family | G3: 0-1945 | H3: 0-1945 | I3: 0-1945 | K3: 0-1945 | L3: 0-1945 | M3: 1000-1965
A4: 2-1 kap 3 laags zadeldak | B4: Semi-detached | D4: End-terraced | G4: 1945-1970 | H4: 1945-1970 | I4: 1945-1975 | K4: 1945-1970 | L4: 1945-1965 | M4: 1000-1965
A5: seriematige woning 3 laags zadeldak | B5: End-terraced | D5: End-terraced | G5: 1970-2000 | H5: 1970-2000 | I5: 1975-1992 | K5: 1945-1970 | L5: 1965-1975
A6: seriematige woning 3 laags zadeldak | B6: Mid-terraced | D6: Mid-terraced | G6: 2000-2014 | H6: 2000-2018 | K6: 1970-2000 | L6: 1975-1992
A7: woonzorgcentrum | B7: Apartment building | D7: Apartment building | E7: Apartment building | G7: 2014-2018 | H7: 2000-2018 | K7: 1970-2000 | L7: 1992-2006
A8: appartementenblok tot 6 lagen | B8: Apartment building | D8: Multi-family building | E8: Apartment building | G8: 2018-2050 | H8: 2018-2050 | K8: 2000-2018 | L8: 2006-2015 | M8: 2006-2021
A9: winkel met appartementen | B9: Other | L9: 2015-2021 | M9: 2006-2021
L10: BENG since 2021
B12: Group Semi-Detached and Hoekwoning (End-terraced) | L12: Group 2006-2021
L13: potentially group 1965-1992
